Workbook
Name _DAT1: #REF!
Name _DAT10: #REF!
Name _DAT11: #REF!
Name _DAT12: #REF!
Name _DAT13: #REF!
Name _DAT14: #REF!
Name _DAT15: #REF!
Name _DAT16: #REF!
Name _DAT17: #REF!
Name _DAT18: #REF!
Name _DAT19: #REF!
Name _DAT2: #REF!
Name _DAT20: #REF!
Name _DAT21: #REF!
Name _DAT22: #REF!
Name _DAT23: #REF!
Name _DAT24: #REF!
Name _DAT25: #REF!
Name _DAT26: #REF!
Name _DAT27: #REF!
Name _DAT28: #REF!
Name _DAT29: #REF!
Name _DAT3: #REF!
Name _DAT30: #REF!
Name _DAT31: #REF!
Name _DAT4: #REF!
Name _DAT5: #REF!
Name _DAT6: #REF!
Name _DAT7: #REF!
Name _DAT8: #REF!
Name _DAT9: #REF!
Name RANGE10: #REF!
Name RANGE103: #REF!
Name RANGE105: #REF!
Name RANGE106: #REF!
Name RANGE107: #REF!
Name RANGE108: #REF!
Name RANGE11: #REF!
Name RANGE112: #REF!
Name RANGE113: #REF!
Name RANGE114: #REF!
Name RANGE115: #REF!
Name RANGE116: #REF!
Name RANGE117: #REF!
Name RANGE118: #REF!
Name RANGE119: #REF!
Name RANGE12: #REF!
Name RANGE120: #REF!
Name RANGE121: #REF!
Name RANGE122: #REF!
Name RANGE125: #REF!
Name RANGE127: #REF!
Name RANGE128: #REF!
Name RANGE129: #REF!
Name RANGE13: #REF!
Name RANGE130: #REF!
Name RANGE131: #REF!
Name RANGE132: #REF!
Name RANGE133: #REF!
Name RANGE134: #REF!

Sheet 后补
B3: 求和项:PE-后补 | D3: 创建月份 | K3: 目前待开票付款
B4: 邮箱 | C4: 客户 | D4: 4月已补建 | E4: 5月已补建 | F4: 6月已补建 | G4: 7月已补建 | H4: 8月建 | I4: 8月待建 | J4: 总计
B5: 曲盛涛 | C5: 贵阳鑫旺隆贸易有限公司 | D5: 3293.5162 | J5: 3293.5162 | K5: 3293.5162
C6: 上海文鑫网络科技有限公司 | D6: 33901.895 | G6: 35996.626 | J6: 69898.521 | K6: 32847.939
C7: 上海薪满翊商贸有限公司 | D7: 2646.6737 | J7: 2646.6737 | K7: 2646.6737
C8: 天宁区雕庄达途百货经营部 | I8: 45838.038 | J8: 45838.038
C9: 成都东森润园商贸有限公司 | I9: 1204.9545 | J9: 1204.9545
C10: 浙江省宁波三江 | I10: 11300 | J10: 11300
B11: 曲盛涛 汇总 | D11: 39842.085 | G11: 35996.626 | I11: 58342.993 | J11: 134181.7 | K11: =SUM(K5:K10) -> 38788.129
B12: 王金邦 | C12: 北京宝诚恒信科技有限公司 | G12: 73183.226 | J12: 73183.226
C13: 北京朝批中得商贸有限公司 | E13: 60325.229 | J13: 60325.229 | K13: 60293.925
C14: 北京泰和嘉华商贸有限公司 | D14: 990.47449 | H14: 5526.4306 | J14: 6516.9051
C15: 大连达博商贸有限公司 | D15: 10853.679 | J15: 10853.679 | K15: 10853.679
C16: 青岛聚鑫美商贸有限公司 | D16: 733.77547 | J16: 733.77547 | K16: 733.77547
C17: 西宁华松商贸有限公司 | D17: 6264.0345 | J17: 6264.0345 | K17: 1614.3421
C18: 大连隆欣商贸有限公司 | I18: 872.14861 | J18: 872.14861
C19: 黑龙江和盛祥供应链管理有限公司 | I19: 70.836576 | J19: 70.836576
C20: 北京卓腾商贸有限公司 | I20: 5669.9452 | J20: 5669.9452
C21: 新疆八点半供应链管理有限公司 | F21: 20143 | H21: 4385.8307 | J21: 24528.831 | K21: 20143
C22: 北京宝诚恒信商贸有限公司 | I22: 3642.5102 | J22: 3642.5102
C23: 伊犁紫金花商贸有限责任公司 | I23: 3092.6974 | J23: 3092.6974
C24: 青岛荣利鑫商贸有限公司 | I24: 328.84817 | J24: 328.84817
C25: 沈阳和盛祥供应链管理有限公司 | I25: 2601.4255 | J25: 2601.4255
C26: 济南华天新光商贸有限公司 | H26: 5999.9997 | J26: 5999.9997
C27: 常州领淘商贸有限公司 | I27: 20583.335 | J27: 20583.335
B28: 王金邦 汇总 | D28: 18841.964 | E28: 60325.229 | F28: 20143 | G28: 73183.226 | H28: 15912.261 | I28: 36861.746 | J28: 225267.43 | K28: =SUM(K12:K27) -> 93638.722
B29: 总计 | D29: 58684.049 | E29: 60325.229 | F29: 20143 | G29: 109179.85 | H29: 15912.261 | I29: 95204.739 | J29: 359449.13 | K29: =K11+K28 -> 132426.85
B39: 求和项:应补偿金额-不含税 | D39: 进度
B40: 邮箱 | C40: 客户 | D40: 待付款 | E40: 待开票付款 | F40: 总计
B41: 曲盛涛 | C41: 上海文鑫网络科技有限公司 | E41: 32847.939 | F41: 32847.939
B42: 曲盛涛 汇总 | E42: 32847.939 | F42: 32847.939
B43: 王金邦 | C43: 北京朝批中得商贸有限公司 | D43: 60293.925 | F43: 60293.925
C44: 西宁华松商贸有限公司 | E44: 1614.3421 | F44: 1614.3421
C45: 新疆八点半供应链管理有限公司 | E45: 20143 | F45: 20143
B46: 王金邦 汇总 | D46: 60293.925 | E46: 21757.342 | F46: 82051.267
B47: 总计 | D47: 60293.925 | E47: 54605.281 | F47: 114899.21

Sheet Offline TTL
A1: 公式 | B1: 公式 | C1: 公式 | E1: RKA销售填写 | F1: 销售填写 | G1: 公式 | H1: 公式 | I1: 公式 | J1: 销售填写 | K1: 公式 | L1: 公式 | M1: 公式 | N1: 公式 | O1: 公式 | P1: 公式 | Q1: 公式 | R1: 公式 | T1: 销售填写 | U1: 销售填写 | V1: 销售填写 | W1: 销售填写 | X1: 销售填写 | Y1: 销售填写 | Z1: 公式 | AA1: 销售填写 | AB1: RKA销售填写 | AC1: 公式 | AD1: NKA销售填写 | AE1: RKA销售填写 | AF1: 公式 | AG1: 公式 | AH1: NKA销售填写 | AI1: 公式 | AJ1: 公式 | AK1: 公式 | AL1: 公式 | AN1: 公式 | AO1: 公式 | AP1: 销售填写 | AQ1: 公式 | AR1: 公式 | AS1: 公式
AA2: 零售商 | AB2: 零售商 | AC2: 零售商 | AD2: 零售商 | AE2: 经销商 | AF2: 经销商 | AH2: 零售商 | AI2: 促销 | AL2: 0603更新
Q3: 未税 | R3: 未税 | T3: 零售价 | W3: 零售价权重 | AC3: 活动 | AD3: EDLP | AF3: 未税 | AG3: *% of GSV | AH3: *% of ISV | AI3: *% of ISV | AJ3: *% of GSV
A4: 客户&SKU | B4: 经销商&SKU | C4: 经销商&客户 | D4: channel | E4: 经销商 | F4: Client | G4: Category | H4: 注 | I4: Size | J4: Product-Code | K4: Material Code | L4: Barcode（EA） | M4: CN Description | N4: Material Name | O4: EA/Case | P4: Pack/EA | Q4: PR00/CS | R4: PR00/EA | T4: A级 | U4: B级-EDLP | V4: S级 | W4: A级 | X4: B级-EDLP | Y4: S级 | Z4: ASP | AA4: 前毛 | AB4: 后毛 | AC4: 促销供价 (未税） | AD4: EDLP供价 (未税） | AE4: 合同点数 | AF4: 经销商提货价 | AG4: PE% | AH4: SD% | AI4: 短促费用% | AJ4: SDR% | AK4: NSV (excl.VAT) | AL4: COGS% | AM4: DE% | AN4: GP | AO4: GP% | AP4: Total Volume (CS) | AQ4: Total NSV | AR4: Total GP | AS4: 2026 GSV
A5: =F5&J5 -> Sam's2169-00 | D5: NKA | F5: Sam's | G5: =VLOOKUP($J5,'mapping-Y26'!#REF!,2,0) -> #REF! | I5: =VLOOKUP($J5,'mapping-Y26'!$F:$L,5,0) -> 14018125 | J5: 2169-00 | K5: =VLOOKUP($J5,'mapping-Y26'!$F:$L,4,0) -> 216900舒洁®北海道牛乳系列乳霜纸面巾80抽6包装 | L5: =VLOOKUP($J5,'mapping-Y26'!#REF!,4,0) -> #REF! | M5: =VLOOKUP($J5,'mapping-Y26'!$H:$L,2,0) -> 216900舒洁®北海道牛乳系列乳霜纸面巾80抽6包装 | N5: =VLOOKUP($J5,'mapping-Y26'!$M:$N,3,0) -> #N/A | O5: =VLOOKUP($J5,'mapping-Y26'!$M:$N,5,0) -> #N/A | P5: =VLOOKUP($J5,'mapping-Y26'!$M:$N,6,0) -> #N/A | Q5: =VLOOKUP($J5,'mapping-Y26'!$M:$Q,7,0) -> #N/A | R5: =Q5/O5 -> #N/A | U5: 45.9 | X5: 1 | Z5: =T5*W5+U5*X5+V5*Y5 -> 45.9 | AA5: 0.1314 | AB5: 0 | AC5: =Z5*(1-AA5-AB5)/1.13 -> 35.282071 | AD5: =208.51245936/O5 -> #N/A | AG5: =(R5-AD5)/R5 -> #N/A | AH5: 0.0304 | AJ5: =(AH5+AI5)*AD5/R5+AG5 -> #N/A | AK5: =R5*(1-AJ5) -> #N/A | AL5: =VLOOKUP($J5,#REF!,12,0) -> #REF! | AM5: 0.027 | AN5: =AK5-R5*(AL5+AM5) -> #N/A | AO5: =AN5/AK5 -> #N/A | AQ5: =O5*AK5*AP5 -> #N/A | AR5: =AP5*AN5*O5 -> #N/A | AS5: =AP5*Q5 -> #N/A
A6: =F6&J6 -> Sam's2609-00 | D6: NKA | F6: Sam's | G6: =VLOOKUP($J6,'mapping-Y26'!#REF!,2,0) -> #REF! | H6: =VLOOKUP($J6,'mapping-Y26'!$F:$L,6,0) -> 8P-65gsm-山姆 | I6: =VLOOKUP($J6,'mapping-Y26'!$F:$L,5,0) -> 14018377 | J6: 2609-00 | K6: =VLOOKUP($J6,'mapping-Y26'!$F:$L,4,0) -> 260900舒洁湿厕纸(65gsm)8片x48包 | L6: =VLOOKUP($J6,'mapping-Y26'!#REF!,4,0) -> #REF! | M6: =VLOOKUP($J6,'mapping-Y26'!$H:$L,2,0) -> 260900舒洁湿厕纸(65gsm)8片x48包 | N6: =VLOOKUP($J6,'mapping-Y26'!M:N,3,0) -> #N/A | O6: =VLOOKUP($J6,'mapping-Y26'!$M:$N,5,0) -> #N/A | P6: =VLOOKUP($J6,'mapping-Y26'!$M:$N,6,0) -> #N/A | Q6: =VLOOKUP($J6,'mapping-Y26'!$M:$Q,7,0) -> #N/A | R6: =Q6/O6 -> #N/A | U6: 49.9 | X6: 1 | Z6: =T6*W6+U6*X6+V6*Y6 -> 49.9 | AA6: 0.13 | AB6: 0 | AC6: =Z6*(1-AA6-AB6)/1.13 -> 38.418584 | AD6: 37.8437 | AG6: =(R6-AD6)/R6 -> #N/A | AH6: 0.0304 | AJ6: =(AH6+AI6)*AD6/R6+AG6 -> #N/A | AK6: =R6*(1-AJ6) -> #N/A | AL6: =VLOOKUP($J6,#REF!,12,0) -> #REF! | AM6: 0.027 | AN6: =AK6-R6*(AL6+AM6) -> #N/A | AO6: =AN6/AK6 -> #N/A | AQ6: =O6*AK6*AP6 -> #N/A | AR6: =AP6*AN6*O6 -> #N/A | AS6: =AP6*Q6 -> #N/A
A7: =F7&J7 -> Walmart2155-03 | D7: NKA | F7: Walmart | G7: =VLOOKUP($J7,'mapping-Y26'!#REF!,2,0) -> #REF! | I7: =VLOOKUP($J7,'mapping-Y26'!$F:$L,5,0) -> 14016306 | J7: 2155-03 | K7: =VLOOKUP($J7,'mapping-Y26'!$F:$L,4,0) -> 215503舒洁®北海道轻牛乳系列乳霜纸面巾40抽3包装 | L7: =VLOOKUP($J7,'mapping-Y26'!#REF!,4,0) -> #REF! | M7: =VLOOKUP($J7,'mapping-Y26'!$H:$L,2,0) -> 215503舒洁®北海道轻牛乳系列乳霜纸面巾40抽3包装 | N7: =VLOOKUP($J7,'mapping-Y26'!M:N,3,0) -> #N/A | O7: =VLOOKUP($J7,'mapping-Y26'!$M:$N,5,0) -> #N/A | P7: =VLOOKUP($J7,'mapping-Y26'!$M:$N,6,0) -> #N/A | Q7: =VLOOKUP($J7,'mapping-Y26'!$M:$Q,7,0) -> #N/A | R7: =Q7/O7 -> #N/A | U7: 9.9 | V7: 7.9 | X7: 0.6 | Y7: 0.4 | Z7: =T7*W7+U7*X7+V7*Y7 -> 9.1 | AA7: 0.2 | AB7: 0 | AC7: =Z7*(1-AA7-AB7)/1.13 -> 6.4424779 | AG7: =(R7-AD7)/R7 -> #N/A | AJ7: =(AH7+AI7)*AD7/R7+AG7 -> #N/A | AK7: =R7*(1-AJ7) -> #N/A | AL7: =VLOOKUP($J7,#REF!,12,0) -> #REF! | AM7: 0.027 | AN7: =AK7-R7*(AL7+AM7) -> #N/A | AO7: =AN7/AK7 -> #N/A | AQ7: =O7*AK7*AP7 -> #N/A | AR7: =AP7*AN7*O7 -> #N/A | AS7: =AP7*Q7 -> #N/A
A8: =F8&J8 -> Watsons2660-10 | D8: NKA | F8: Watsons | G8: =VLOOKUP($J8,'mapping-Y26'!#REF!,2,0) -> #REF! | H8: =VLOOKUP($J8,'mapping-Y26'!$F:$L,6,0) -> 80P | I8: =VLOOKUP($J8,'mapping-Y26'!$F:$L,5,0) -> 14017865 | J8: 2660-10 | K8: =VLOOKUP($J8,'mapping-Y26'!$F:$L,4,0) -> 266010舒洁湿厕纸80片 | L8: =VLOOKUP($J8,'mapping-Y26'!#REF!,4,0) -> #REF! | M8: =VLOOKUP($J8,'mapping-Y26'!$H:$L,2,0) -> 266010舒洁湿厕纸80片 | N8: =VLOOKUP($J8,'mapping-Y26'!M:N,3,0) -> #N/A | O8: =VLOOKUP($J8,'mapping-Y26'!$M:$N,5,0) -> #N/A | P8: =VLOOKUP($J8,'mapping-Y26'!$M:$N,6,0) -> #N/A | Q8: =VLOOKUP($J8,'mapping-Y26'!$M:$Q,7,0) -> #N/A | R8: =Q8/O8 -> #N/A | U8: 10 | V8: =25/3 -> 8.3333333 | X8: 0.6 | Y8: 0.4 | Z8: =T8*W8+U8*X8+V8*Y8 -> 9.3333333 | AA8: 0.25 | AB8: 0 | AC8: =Z8*(1-AA8-AB8)/1.13 -> 6.1946903 | AD8: 11.414894 | AG8: =(R8-AD8)/R8 -> #N/A | AH8: =25%*AC8/R8 -> #N/A | AI8: =(AD8-AC8)/AD8 -> 0.45731511 | AJ8: =(AH8+AI8)*AD8/R8+AG8 -> #N/A | AK8: =R8*(1-AJ8) -> #N/A | AL8: =VLOOKUP($J8,#REF!,12,0) -> #REF! | AM8: 0.027 | AN8: =AK8-R8*(AL8+AM8) -> #N/A | AO8: =AN8/AK8 -> #N/A | AQ8: =O8*AK8*AP8 -> #N/A | AR8: =AP8*AN8*O8 -> #N/A | AS8: =AP8*Q8 -> #N/A
A9: =F9&J9 -> Watsons2694-50 | D9: NKA | F9: Watsons | G9: =VLOOKUP($J9,'mapping-Y26'!#REF!,2,0) -> #REF! | H9: =VLOOKUP($J9,'mapping-Y26'!$F:$L,6,0) -> 40P-55gsm | I9: =VLOOKUP($J9,'mapping-Y26'!$F:$L,5,0) -> 14017864 | J9: 2694-50 | K9: =VLOOKUP($J9,'mapping-Y26'!$F:$L,4,0) -> D269450舒洁湿厕纸家庭装40抽 | L9: =VLOOKUP($J9,'mapping-Y26'!#REF!,4,0) -> #REF! | M9: =VLOOKUP($J9,'mapping-Y26'!$H:$L,2,0) -> D269450舒洁湿厕纸家庭装40抽 | N9: =VLOOKUP($J9,'mapping-Y26'!M:N,3,0) -> #N/A | O9: =VLOOKUP($J9,'mapping-Y26'!$M:$N,5,0) -> #N/A | P9: =VLOOKUP($J9,'mapping-Y26'!$M:$N,6,0) -> #N/A | Q9: =VLOOKUP($J9,'mapping-Y26'!$M:$Q,7,0) -> #N/A | R9: =Q9/O9 -> #N/A | U9: 7.5 | V9: 6 | X9: 0.5 | Y9: 0.5 | Z9: =T9*W9+U9*X9+V9*Y9 -> 6.75 | AA9: 0.25 | AB9: 0 | AC9: =Z9*(1-AA9-AB9)/1.13 -> 4.4800885 | AD9: 9.188 | AG9: =(R9-AD9)/R9 -> #N/A | AH9: =25%*AC9/R9 -> #N/A | AI9: =(AD9-AC9)/AD9 -> 0.51239786 | AJ9: =(AH9+AI9)*AD9/R9+AG9 -> #N/A | AK9: =R9*(1-AJ9) -> #N/A | AL9: =VLOOKUP($J9,#REF!,12,0) -> #REF! | AM9: 0.027 | AN9: =AK9-R9*(AL9+AM9) -> #N/A | AO9: =AN9/AK9 -> #N/A | AQ9: =O9*AK9*AP9 -> #N/A | AR9: =AP9*AN9*O9 -> #N/A | AS9: =AP9*Q9 -> #N/A
A10: =F10&J10 -> Watsons2673-00 | D10: NKA | F10: Watsons | G10: =VLOOKUP($J10,'mapping-Y26'!#REF!,2,0) -> #REF! | H10: =VLOOKUP($J10,'mapping-Y26'!$F:$L,6,0) -> 60P | I10: =VLOOKUP($J10,'mapping-Y26'!$F:$L,5,0) -> 14016683 | J10: 2673-00 | K10: =VLOOKUP($J10,'mapping-Y26'!$F:$L,4,0) -> 267300舒洁®山茶花系列湿巾（湿厕纸）60片 | L10: =VLOOKUP($J10,'mapping-Y26'!#REF!,4,0) -> #REF! | M10: =VLOOKUP($J10,'mapping-Y26'!$H:$L,2,0) -> 267300舒洁®山茶花系列湿巾（湿厕纸）60片 | N10: =VLOOKUP($J10,'mapping-Y26'!M:N,3,0) -> #N/A | O10: =VLOOKUP($J10,'mapping-Y26'!$M:$N,5,0) -> #N/A | P10: =VLOOKUP($J10,'mapping-Y26'!$M:$N,6,0) -> #N/A | Q10: =VLOOKUP($J10,'mapping-Y26'!$M:$Q,7,0) -> #N/A | R10: =Q10/O10 -> #N/A | U10: 10 | V10: =25/3 -> 8.3333333 | X10: 0.6 | Y10: 0.4 | Z10: =T10*W10+U10*X10+V10*Y10 -> 9.3333333 | AA10: 0.25 | AB10: 0 | AC10: =Z10*(1-AA10-AB10)/1.13 -> 6.1946903 | AD10: =40.8/4 -> 10.2 | AG10: =(R10-AD10)/R10 -> #N/A | AH10: =25%*AC10/R10 -> #N/A | AI10: =(AD10-AC10)/AD10 -> 0.39267742 | AJ10: =(AH10+AI10)*AD10/R10+AG10 -> #N/A | AK10: =R10*(1-AJ10) -> #N/A | AL10: =VLOOKUP($J10,#REF!,12,0) -> #REF! | AM10: 0.027 | AN10: =AK10-R10*(AL10+AM10) -> #N/A | AO10: =AN10/AK10 -> #N/A | AQ10: =O10*AK10*AP10 -> #N/A | AR10: =AP10*AN10*O10 -> #N/A | AS10: =AP10*Q10 -> #N/A
A11: =F11&J11 -> Watsons2155-03 | D11: NKA | F11: Watsons | G11: =VLOOKUP($J11,'mapping-Y26'!#REF!,2,0) -> #REF! | I11: =VLOOKUP($J11,'mapping-Y26'!$F:$L,5,0) -> 14016306 | J11: 2155-03 | K11: =VLOOKUP($J11,'mapping-Y26'!$F:$L,4,0) -> 215503舒洁®北海道轻牛乳系列乳霜纸面巾40抽3包装 | L11: =VLOOKUP($J11,'mapping-Y26'!#REF!,4,0) -> #REF! | M11: =VLOOKUP($J11,'mapping-Y26'!$H:$L,2,0) -> 215503舒洁®北海道轻牛乳系列乳霜纸面巾40抽3包装 | N11: =VLOOKUP($J11,'mapping-Y26'!M:N,3,0) -> #N/A | O11: =VLOOKUP($J11,'mapping-Y26'!$M:$N,5,0) -> #N/A | P11: =VLOOKUP($J11,'mapping-Y26'!$M:$N,6,0) -> #N/A | Q11: =VLOOKUP($J11,'mapping-Y26'!$M:$Q,7,0) -> #N/A | R11: =Q11/O11 -> #N/A | U11: 12.5 | V11: 9.9 | X11: 0.5 | Y11: 0.5 | Z11: =T11*W11+U11*X11+V11*Y11 -> 11.2 | AA11: 0.25 | AB11: 0 | AC11: =Z11*(1-AA11-AB11)/1.13 -> 7.4336283 | AD11: =R11 -> #N/A | AG11: =(R11-AD11)/R11 -> #N/A | AH11: =25%*AC11/R11 -> #N/A | AI11: =(AD11-AC11)/AD11 -> #N/A | AJ11: =(AH11+AI11)*AD11/R11+AG11 -> #N/A | AK11: =R11*(1-AJ11) -> #N/A | AL11: =VLOOKUP($J11,#REF!,12,0) -> #REF! | AM11: 0.027 | AN11: =AK11-R11*(AL11+AM11) -> #N/A | AO11: =AN11/AK11 -> #N/A | AQ11: =O11*AK11*AP11 -> #N/A | AR11: =AP11*AN11*O11 -> #N/A | AS11: =AP11*Q11 -> #N/A
A12: =F12&J12 -> Watsons2653-00 | D12: NKA | F12: Watsons | G12: =VLOOKUP($J12,'mapping-Y26'!#REF!,2,0) -> #REF! | H12: =VLOOKUP($J12,'mapping-Y26'!$F:$L,6,0) -> 40P-小熊 | I12: =VLOOKUP($J12,'mapping-Y26'!$F:$L,5,0) -> 14018677 | J12: 2653-00 | K12: =VLOOKUP($J12,'mapping-Y26'!$F:$L,4,0) -> 2653-00舒洁小熊湿厕纸40片 | L12: =VLOOKUP($J12,'mapping-Y26'!#REF!,4,0) -> #REF! | M12: =VLOOKUP($J12,'mapping-Y26'!$H:$L,2,0) -> 2653-00舒洁小熊湿厕纸40片 | N12: =VLOOKUP($J12,'mapping-Y26'!M:N,3,0) -> #N/A | O12: =VLOOKUP($J12,'mapping-Y26'!$M:$N,5,0) -> #N/A | P12: =VLOOKUP($J12,'mapping-Y26'!$M:$N,6,0) -> #N/A | Q12: =VLOOKUP($J12,'mapping-Y26'!$M:$Q,7,0) -> #N/A | R12: =Q12/O12 -> #N/A | Z12: =T12*W12+U12*X12+V12*Y12 -> 0 | AA12: 0.25 | AB12: 0 | AC12: =Z12*(1-AA12-AB12)/1.13 -> 0 | AG12: =(R12-AD12)/R12 -> #N/A | AJ12: =(AH12+AI12)*AD12/R12+AG12 -> #N/A | AK12: =R12*(1-AJ12) -> #N/A | AL12: =VLOOKUP($J12,#REF!,12,0) -> #REF! | AM12: 0.027 | AN12: =AK12-R12*(AL12+AM12) -> #N/A | AO12: =AN12/AK12 -> #N/A | AQ12: =O12*AK12*AP12 -> #N/A | AR12: =AP12*AN12*O12 -> #N/A | AS12: =AP12*Q12 -> #N/A
A13: =F13&J13 -> Watsons2657-00 | D13: NKA | F13: Watsons | G13: =VLOOKUP($J13,'mapping-Y26'!#REF!,2,0) -> #REF! | H13: =VLOOKUP($J13,'mapping-Y26'!$F:$L,6,0) -> 80P-小熊 | I13: =VLOOKUP($J13,'mapping-Y26'!$F:$L,5,0) -> 14018689 | J13: 2657-00 | K13: =VLOOKUP($J13,'mapping-Y26'!$F:$L,4,0) -> 2657-00舒洁小熊湿厕纸80片 | L13: =VLOOKUP($J13,'mapping-Y26'!#REF!,4,0) -> #REF! | M13: =VLOOKUP($J13,'mapping-Y26'!$H:$L,2,0) -> 2657-00舒洁小熊湿厕纸80片 | N13: =VLOOKUP($J13,'mapping-Y26'!M:N,3,0) -> #N/A | O13: =VLOOKUP($J13,'mapping-Y26'!$M:$N,5,0) -> #N/A | P13: =VLOOKUP($J13,'mapping-Y26'!$M:$N,6,0) -> #N/A | Q13: =VLOOKUP($J13,'mapping-Y26'!$M:$Q,7,0) -> #N/A | R13: =Q13/O13 -> #N/A | Z13: =T13*W13+U13*X13+V13*Y13 -> 0 | AA13: 0.25 | AB13: 0 | AC13: =Z13*(1-AA13-AB13)/1.13 -> 0 | AG13: =(R13-AD13)/R13 -> #N/A | AJ13: =(AH13+AI13)*AD13/R13+AG13 -> #N/A | AK13: =R13*(1-AJ13) -> #N/A | AL13: =VLOOKUP($J13,#REF!,12,0) -> #REF! | AN13: =AK13-R13*(AL13+AM13) -> #N/A | AO13: =AN13/AK13 -> #N/A | AQ13: =O13*AK13*AP13 -> #N/A | AR13: =AP13*AN13*O13 -> #N/A | AS13: =AP13*Q13 -> #N/A
A14: =F14&J14 -> Metro2662-10 | D14: NKA | F14: Metro | G14: =VLOOKUP($J14,'mapping-Y26'!#REF!,2,0) -> #REF! | H14: =VLOOKUP($J14,'mapping-Y26'!$F:$L,6,0) -> 80P | I14: =VLOOKUP($J14,'mapping-Y26'!$F:$L,5,0) -> 14017868 | J14: 2662-10 | K14: =VLOOKUP($J14,'mapping-Y26'!$F:$L,4,0) -> 266210舒洁湿厕纸80片x6包 | L14: =VLOOKUP($J14,'mapping-Y26'!#REF!,4,0) -> #REF! | M14: =VLOOKUP($J14,'mapping-Y26'!$H:$L,2,0) -> 266210舒洁湿厕纸80片x6包 | N14: =VLOOKUP($J14,'mapping-Y26'!M:N,3,0) -> #N/A | O14: =VLOOKUP($J14,'mapping-Y26'!$M:$N,5,0) -> #N/A | P14: =VLOOKUP($J14,'mapping-Y26'!$M:$N,6,0) -> #N/A | Q14: =VLOOKUP($J14,'mapping-Y26'!$M:$Q,7,0) -> #N/A | R14: =Q14/O14 -> #N/A | U14: 44.9 | X14: 1 | Z14: =T14*W14+U14*X14+V14*Y14 -> 44.9 | AA14: 0.175 | AB14: 0 | AC14: =Z14*(1-AA14-AB14)/1.13 -> 32.780973 | AD14: =37/1.13 -> 32.743363 | AG14: =(R14-AD14)/R14 -> #N/A | AH14: =11.87%*0.25+16.5%*0.75 -> 0.153425 | AJ14: =(AH14+AI14)*AD14/R14+AG14 -> #N/A | AK14: =R14*(1-AJ14) -> #N/A | AL14: =VLOOKUP($J14,#REF!,12,0) -> #REF! | AM14: 0.027 | AN14: =AK14-R14*(AL14+AM14) -> #N/A | AO14: =AN14/AK14 -> #N/A | AQ14: =O14*AK14*AP14 -> #N/A | AR14: =AP14*AN14*O14 -> #N/A | AS14: =AP14*Q14 -> #N/A
A15: =F15&J15 -> 大润发东区2660-10 | D15: NKA | F15: 大润发东区 | G15: =VLOOKUP($J15,'mapping-Y26'!#REF!,2,0) -> #REF! | H15: =VLOOKUP($J15,'mapping-Y26'!$F:$L,6,0) -> 80P | I15: =VLOOKUP($J15,'mapping-Y26'!$F:$L,5,0) -> 14017865 | J15: 2660-10 | K15: =VLOOKUP($J15,'mapping-Y26'!$F:$L,4,0) -> 266010舒洁湿厕纸80片 | L15: =VLOOKUP($J15,'mapping-Y26'!#REF!,4,0) -> #REF! | M15: =VLOOKUP($J15,'mapping-Y26'!$H:$L,2,0) -> 266010舒洁湿厕纸80片 | N15: =VLOOKUP($J15,'mapping-Y26'!M:N,3,0) -> #N/A | O15: =VLOOKUP($J15,'mapping-Y26'!$M:$N,5,0) -> #N/A | P15: =VLOOKUP($J15,'mapping-Y26'!$M:$N,6,0) -> #N/A | Q15: =VLOOKUP($J15,'mapping-Y26'!$M:$Q,7,0) -> #N/A | R15: =Q15/O15 -> #N/A | U15: 9.9 | X15: 1 | Z15: =T15*W15+U15*X15+V15*Y15 -> 9.9 | AA15: 0.1 | AB15: 0 | AC15: =Z15*(1-AA15-AB15)/1.13 -> 7.8849558 | AG15: =(R15-AD15)/R15 -> #N/A | AJ15: =(AH15+AI15)*AD15/R15+AG15 -> #N/A | AK15: =R15*(1-AJ15) -> #N/A | AL15: =VLOOKUP($J15,#REF!,12,0) -> #REF! | AM15: 0.027 | AN15: =AK15-R15*(AL15+AM15) -> #N/A | AO15: =AN15/AK15 -> #N/A | AQ15: =O15*AK15*AP15 -> #N/A | AR15: =AP15*AN15*O15 -> #N/A | AS15: =AP15*Q15 -> #N/A
A16: =F16&J16 -> 大润发东区2694-50 | D16: NKA | F16: 大润发东区 | G16: =VLOOKUP($J16,'mapping-Y26'!#REF!,2,0) -> #REF! | H16: =VLOOKUP($J16,'mapping-Y26'!$F:$L,6,0) -> 40P-55gsm | I16: =VLOOKUP($J16,'mapping-Y26'!$F:$L,5,0) -> 14017864 | J16: 2694-50 | K16: =VLOOKUP($J16,'mapping-Y26'!$F:$L,4,0) -> D269450舒洁湿厕纸家庭装40抽 | L16: =VLOOKUP($J16,'mapping-Y26'!#REF!,4,0) -> #REF! | M16: =VLOOKUP($J16,'mapping-Y26'!$H:$L,2,0) -> D269450舒洁湿厕纸家庭装40抽 | N16: =VLOOKUP($J16,'mapping-Y26'!M:N,3,0) -> #N/A | O16: =VLOOKUP($J16,'mapping-Y26'!$M:$N,5,0) -> #N/A | P16: =VLOOKUP($J16,'mapping-Y26'!$M:$N,6,0) -> #N/A | Q16: =VLOOKUP($J16,'mapping-Y26'!$M:$Q,7,0) -> #N/A | R16: =Q16/O16 -> #N/A | U16: 6.9 | X16: 1 | Z16: =T16*W16+U16*X16+V16*Y16 -> 6.9 | AA16: 0.1 | AB16: 0 | AC16: =Z16*(1-AA16-AB16)/1.13 -> 5.4955752 | AG16: =(R16-AD16)/R16 -> #N/A | AJ16: =(AH16+AI16)*AD16/R16+AG16 -> #N/A | AK16: =R16*(1-AJ16) -> #N/A | AL16: =VLOOKUP($J16,#REF!,12,0) -> #REF! | AM16: 0.027 | AN16: =AK16-R16*(AL16+AM16) -> #N/A | AO16: =AN16/AK16 -> #N/A | AQ16: =O16*AK16*AP16 -> #N/A | AR16: =AP16*AN16*O16 -> #N/A | AS16: =AP16*Q16 -> #N/A
A17: =F17&J17 -> 大润发东区2291-60 | D17: NKA | F17: 大润发东区 | G17: =VLOOKUP($J17,'mapping-Y26'!#REF!,2,0) -> #REF! | I17: =VLOOKUP($J17,'mapping-Y26'!$F:$L,5,0) -> 14014479 | J17: 2291-60 | K17: =VLOOKUP($J17,'mapping-Y26'!$F:$L,4,0) -> 229160舒洁绿茶洋甘菊印花清香卷纸10粒 | L17: =VLOOKUP($J17,'mapping-Y26'!#REF!,4,0) -> #REF! | M17: =VLOOKUP($J17,'mapping-Y26'!$H:$L,2,0) -> 229160舒洁绿茶洋甘菊印花清香卷纸10粒 | N17: =VLOOKUP($J17,'mapping-Y26'!M:N,3,0) -> #N/A | O17: =VLOOKUP($J17,'mapping-Y26'!$M:$N,5,0) -> #N/A | P17: =VLOOKUP($J17,'mapping-Y26'!$M:$N,6,0) -> #N/A | Q17: =VLOOKUP($J17,'mapping-Y26'!$M:$Q,7,0) -> #N/A | R17: =Q17/O17 -> #N/A | U17: 32.9 | X17: 1 | Z17: =T17*W17+U17*X17+V17*Y17 -> 32.9 | AA17: 0.1 | AB17: 0 | AC17: =Z17*(1-AA17-AB17)/1.13 -> 26.20354 | AG17: =(R17-AD17)/R17 -> #N/A | AJ17: =(AH17+AI17)*AD17/R17+AG17 -> #N/A | AK17: =R17*(1-AJ17) -> #N/A | AL17: =VLOOKUP($J17,#REF!,12,0) -> #REF! | AM17: 0.027 | AN17: =AK17-R17*(AL17+AM17) -> #N/A | AO17: =AN17/AK17 -> #N/A | AQ17: =O17*AK17*AP17 -> #N/A | AR17: =AP17*AN17*O17 -> #N/A | AS17: =AP17*Q17 -> #N/A
A18: =F18&J18 -> 大润发南区2660-10 | D18: NKA | F18: 大润发南区 | G18: =VLOOKUP($J18,'mapping-Y26'!#REF!,2,0) -> #REF! | H18: =VLOOKUP($J18,'mapping-Y26'!$F:$L,6,0) -> 80P | I18: =VLOOKUP($J18,'mapping-Y26'!$F:$L,5,0) -> 14017865 | J18: 2660-10 | K18: =VLOOKUP($J18,'mapping-Y26'!$F:$L,4,0) -> 266010舒洁湿厕纸80片 | L18: =VLOOKUP($J18,'mapping-Y26'!#REF!,4,0) -> #REF! | M18: =VLOOKUP($J18,'mapping-Y26'!$H:$L,2,0) -> 266010舒洁湿厕纸80片 | N18: =VLOOKUP($J18,'mapping-Y26'!M:N,3,0) -> #N/A | O18: =VLOOKUP($J18,'mapping-Y26'!$M:$N,5,0) -> #N/A | P18: =VLOOKUP($J18,'mapping-Y26'!$M:$N,6,0) -> #N/A | Q18: =VLOOKUP($J18,'mapping-Y26'!$M:$Q,7,0) -> #N/A | R18: =Q18/O18 -> #N/A | U18: 19.9 | X18: 1 | Z18: =T18*W18+U18*X18+V18*Y18 -> 19.9 | AA18: 0.1 | AB18: 0 | AC18: =Z18*(1-AA18-AB18)/1.13 -> 15.849558 | AG18: =(R18-AD18)/R18 -> #N/A | AJ18: =(AH18+AI18)*AD18/R18+AG18 -> #N/A | AK18: =R18*(1-AJ18) -> #N/A | AL18: =VLOOKUP($J18,#REF!,12,0) -> #REF! | AM18: 0.027 | AN18: =AK18-R18*(AL18+AM18) -> #N/A | AO18: =AN18/AK18 -> #N/A | AQ18: =O18*AK18*AP18 -> #N/A | AR18: =AP18*AN18*O18 -> #N/A | AS18: =AP18*Q18 -> #N/A
A19: =F19&J19 -> 大润发南区2694-50 | D19: NKA | F19: 大润发南区 | G19: =VLOOKUP($J19,'mapping-Y26'!#REF!,2,0) -> #REF! | H19: =VLOOKUP($J19,'mapping-Y26'!$F:$L,6,0) -> 40P-55gsm | I19: =VLOOKUP($J19,'mapping-Y26'!$F:$L,5,0) -> 14017864 | J19: 2694-50 | K19: =VLOOKUP($J19,'mapping-Y26'!$F:$L,4,0) -> D269450舒洁湿厕纸家庭装40抽 | L19: =VLOOKUP($J19,'mapping-Y26'!#REF!,4,0) -> #REF! | M19: =VLOOKUP($J19,'mapping-Y26'!$H:$L,2,0) -> D269450舒洁湿厕纸家庭装40抽 | N19: =VLOOKUP($J19,'mapping-Y26'!M:N,3,0) -> #N/A | O19: =VLOOKUP($J19,'mapping-Y26'!$M:$N,5,0) -> #N/A | P19: =VLOOKUP($J19,'mapping-Y26'!$M:$N,6,0) -> #N/A | Q19: =VLOOKUP($J19,'mapping-Y26'!$M:$Q,7,0) -> #N/A | R19: =Q19/O19 -> #N/A | U19: 6.9 | X19: 1 | Z19: =T19*W19+U19*X19+V19*Y19 -> 6.9 | AA19: 0.1 | AB19: 0 | AC19: =Z19*(1-AA19-AB19)/1.13 -> 5.4955752 | AG19: =(R19-AD19)/R19 -> #N/A | AJ19: =(AH19+AI19)*AD19/R19+AG19 -> #N/A | AK19: =R19*(1-AJ19) -> #N/A | AL19: =VLOOKUP($J19,#REF!,12,0) -> #REF! | AM19: 0.027 | AN19: =AK19-R19*(AL19+AM19) -> #N/A | AO19: =AN19/AK19 -> #N/A | AQ19: =O19*AK19*AP19 -> #N/A | AR19: =AP19*AN19*O19 -> #N/A | AS19: =AP19*Q19 -> #N/A
A20: =F20&J20 -> 大润发南区2661-10 | D20: NKA | F20: 大润发南区 | G20: =VLOOKUP($J20,'mapping-Y26'!#REF!,2,0) -> #REF! | H20: =VLOOKUP($J20,'mapping-Y26'!$F:$L,6,0) -> 80P-55gsm | I20: =VLOOKUP($J20,'mapping-Y26'!$F:$L,5,0) -> 14017866 | J20: 2661-10 | K20: =VLOOKUP($J20,'mapping-Y26'!$F:$L,4,0) -> 266110舒洁湿厕纸80片x3包 | L20: =VLOOKUP($J20,'mapping-Y26'!#REF!,4,0) -> #REF! | M20: =VLOOKUP($J20,'mapping-Y26'!$H:$L,2,0) -> 266110舒洁湿厕纸80片x3包 | N20: =VLOOKUP($J20,'mapping-Y26'!M:N,3,0) -> #N/A | O20: =VLOOKUP($J20,'mapping-Y26'!$M:$N,5,0) -> #N/A | P20: =VLOOKUP($J20,'mapping-Y26'!$M:$N,6,0) -> #N/A | Q20: =VLOOKUP($J20,'mapping-Y26'!$M:$Q,7,0) -> #N/A | R20: =Q20/O20 -> #N/A | U20: 29.9 | X20: 1 | Z20: =T20*W20+U20*X20+V20*Y20 -> 29.9 | AA20: 0.1 | AB20: 0 | AC20: =Z20*(1-AA20-AB20)/1.13 -> 23.814159 | AG20: =(R20-AD20)/R20 -> #N/A | AJ20: =(AH20+AI20)*AD20/R20+AG20 -> #N/A | AK20: =R20*(1-AJ20) -> #N/A | AL20: =VLOOKUP($J20,#REF!,12,0) -> #REF! | AM20: 0.027 | AN20: =AK20-R20*(AL20+AM20) -> #N/A | AO20: =AN20/AK20 -> #N/A | AQ20: =O20*AK20*AP20 -> #N/A | AR20: =AP20*AN20*O20 -> #N/A | AS20: =AP20*Q20 -> #N/A
A21: =F21&J21 -> 大润发南区2162-08 | D21: NKA | F21: 大润发南区 | G21: =VLOOKUP($J21,'mapping-Y26'!#REF!,2,0) -> #REF! | I21: =VLOOKUP($J21,'mapping-Y26'!$F:$L,5,0) -> 14015110 | J21: 2162-08 | K21: =VLOOKUP($J21,'mapping-Y26'!$F:$L,4,0) -> 216208舒洁®北海道牛乳系列乳霜纸面巾20抽8包装 | L21: =VLOOKUP($J21,'mapping-Y26'!#REF!,4,0) -> #REF! | M21: =VLOOKUP($J21,'mapping-Y26'!$H:$L,2,0) -> 216208舒洁®北海道牛乳系列乳霜纸面巾20抽8包装 | N21: =VLOOKUP($J21,'mapping-Y26'!M:N,3,0) -> #N/A | O21: =VLOOKUP($J21,'mapping-Y26'!$M:$N,5,0) -> #N/A | P21: =VLOOKUP($J21,'mapping-Y26'!$M:$N,6,0) -> #N/A | Q21: =VLOOKUP($J21,'mapping-Y26'!$M:$Q,7,0) -> #N/A | R21: =Q21/O21 -> #N/A | U21: 21.9 | X21: 1 | Z21: =T21*W21+U21*X21+V21*Y21 -> 21.9 | AA21: 0.1 | AB21: 0 | AC21: =Z21*(1-AA21-AB21)/1.13 -> 17.442478 | AG21: =(R21-AD21)/R21 -> #N/A | AJ21: =(AH21+AI21)*AD21/R21+AG21 -> #N/A | AK21: =R21*(1-AJ21) -> #N/A | AL21: =VLOOKUP($J21,#REF!,12,0) -> #REF! | AM21: 0.027 | AN21: =AK21-R21*(AL21+AM21) -> #N/A | AO21: =AN21/AK21 -> #N/A | AQ21: =O21*AK21*AP21 -> #N/A | AR21: =AP21*AN21*O21 -> #N/A | AS21: =AP21*Q21 -> #N/A
A22: =F22&J22 -> 大润发南区2103-90 | D22: NKA | F22: 大润发南区 | G22: =VLOOKUP($J22,'mapping-Y26'!#REF!,2,0) -> #REF! | I22: =VLOOKUP($J22,'mapping-Y26'!$F:$L,5,0) -> 14016868 | J22: 2103-90 | K22: =VLOOKUP($J22,'mapping-Y26'!$F:$L,4,0) -> 210390舒洁小熊印花抽纸3层80抽4包FSC mix70% | L22: =VLOOKUP($J22,'mapping-Y26'!#REF!,4,0) -> #REF! | M22: =VLOOKUP($J22,'mapping-Y26'!$H:$L,2,0) -> 210390舒洁小熊印花抽纸3层80抽4包FSC mix70% | N22: =VLOOKUP($J22,'mapping-Y26'!M:N,3,0) -> #N/A | O22: =VLOOKUP($J22,'mapping-Y26'!$M:$N,5,0) -> #N/A | P22: =VLOOKUP($J22,'mapping-Y26'!$M:$N,6,0) -> #N/A | Q22: =VLOOKUP($J22,'mapping-Y26'!$M:$Q,7,0) -> #N/A | R22: =Q22/O22 -> #N/A | U22: 15.5 | X22: 1 | Z22: =T22*W22+U22*X22+V22*Y22 -> 15.5 | AA22: 0.1 | AB22: 0 | AC22: =Z22*(1-AA22-AB22)/1.13 -> 12.345133 | AG22: =(R22-AD22)/R22 -> #N/A | AJ22: =(AH22+AI22)*AD22/R22+AG22 -> #N/A | AK22: =R22*(1-AJ22) -> #N/A | AL22: =VLOOKUP($J22,#REF!,12,0) -> #REF! | AM22: 0.027 | AN22: =AK22-R22*(AL22+AM22) -> #N/A | AO22: =AN22/AK22 -> #N/A | AQ22: =O22*AK22*AP22 -> #N/A | AR22: =AP22*AN22*O22 -> #N/A | AS22: =AP22*Q22 -> #N/A
A23: =F23&J23 -> 大润发南区2107-61 | D23: NKA | F23: 大润发南区 | G23: =VLOOKUP($J23,'mapping-Y26'!#REF!,2,0) -> #REF! | I23: =VLOOKUP($J23,'mapping-Y26'!$F:$L,5,0) -> 14014470 | J23: 2107-61 | K23: =VLOOKUP($J23,'mapping-Y26'!$F:$L,4,0) -> 210761舒洁卡通系列抽纸200抽3包 FSC mix70% | L23: =VLOOKUP($J23,'mapping-Y26'!#REF!,4,0) -> #REF! | M23: =VLOOKUP($J23,'mapping-Y26'!$H:$L,2,0) -> 210761舒洁卡通系列抽纸200抽3包 FSC mix70% | N23: =VLOOKUP($J23,'mapping-Y26'!M:N,3,0) -> #N/A | O23: =VLOOKUP($J23,'mapping-Y26'!$M:$N,5,0) -> #N/A | P23: =VLOOKUP($J23,'mapping-Y26'!$M:$N,6,0) -> #N/A | Q23: =VLOOKUP($J23,'mapping-Y26'!$M:$Q,7,0) -> #N/A | R23: =Q23/O23 -> #N/A | U23: 20.9 | X23: 1 | Z23: =T23*W23+U23*X23+V23*Y23 -> 20.9 | AA23: 0.1 | AB23: 0 | AC23: =Z23*(1-AA23-AB23)/1.13 -> 16.646018 | AG23: =(R23-AD23)/R23 -> #N/A | AJ23: =(AH23+AI23)*AD23/R23+AG23 -> #N/A | AK23: =R23*(1-AJ23) -> #N/A | AL23: =VLOOKUP($J23,#REF!,12,0) -> #REF! | AM23: 0.027 | AN23: =AK23-R23*(AL23+AM23) -> #N/A | AO23: =AN23/AK23 -> #N/A | AQ23: =O23*AK23*AP23 -> #N/A | AR23: =AP23*AN23*O23 -> #N/A | AS23: =AP23*Q23 -> #N/A
A24: =F24&J24 -> 大润发南区2312-16 | D24: NKA | F24: 大润发南区 | G24: =VLOOKUP($J24,'mapping-Y26'!#REF!,2,0) -> #REF! | I24: =VLOOKUP($J24,'mapping-Y26'!$F:$L,5,0) -> 14014482 | J24: 2312-16 | K24: =VLOOKUP($J24,'mapping-Y26'!$F:$L,4,0) -> 231216 舒洁马蹄莲盒面纸200抽3盒 FSC mix70% | L24: =VLOOKUP($J24,'mapping-Y26'!#REF!,4,0) -> #REF! | M24: =VLOOKUP($J24,'mapping-Y26'!$H:$L,2,0) -> 231216 舒洁马蹄莲盒面纸200抽3盒 FSC mix70% | N24: =VLOOKUP($J24,'mapping-Y26'!M:N,3,0) -> #N/A | O24: =VLOOKUP($J24,'mapping-Y26'!$M:$N,5,0) -> #N/A | P24: =VLOOKUP($J24,'mapping-Y26'!$M:$N,6,0) -> #N/A | Q24: =VLOOKUP($J24,'mapping-Y26'!$M:$Q,7,0) -> #N/A | R24: =Q24/O24 -> #N/A | U24: 29.7 | X24: 1 | Z24: =T24*W24+U24*X24+V24*Y24 -> 29.7 | AA24: 0.1 | AB24: 0 | AC24: =Z24*(1-AA24-AB24)/1.13 -> 23.654867 | AG24: =(R24-AD24)/R24 -> #N/A | AJ24: =(AH24+AI24)*AD24/R24+AG24 -> #N/A | AK24: =R24*(1-AJ24) -> #N/A | AL24: =VLOOKUP($J24,#REF!,12,0) -> #REF! | AM24: 0.027 | AN24: =AK24-R24*(AL24+AM24) -> #N/A | AO24: =AN24/AK24 -> #N/A | AQ24: =O24*AK24*AP24 -> #N/A | AR24: =AP24*AN24*O24 -> #N/A | AS24: =AP24*Q24 -> #N/A
A25: =F25&J25 -> 大润发南区2701-90 | D25: NKA | F25: 大润发南区 | G25: =VLOOKUP($J25,'mapping-Y26'!#REF!,2,0) -> #REF! | I25: =VLOOKUP($J25,'mapping-Y26'!$F:$L,5,0) -> 14016871 | J25: 2701-90 | K25: =VLOOKUP($J25,'mapping-Y26'!$F:$L,4,0) -> 270190舒洁小熊印花手帕纸3层10包FSC mix70% | L25: =VLOOKUP($J25,'mapping-Y26'!#REF!,4,0) -> #REF! | M25: =VLOOKUP($J25,'mapping-Y26'!$H:$L,2,0) -> 270190舒洁小熊印花手帕纸3层10包FSC mix70% | N25: =VLOOKUP($J25,'mapping-Y26'!M:N,3,0) -> #N/A | O25: =VLOOKUP($J25,'mapping-Y26'!$M:$N,5,0) -> #N/A | P25: =VLOOKUP($J25,'mapping-Y26'!$M:$N,6,0) -> #N/A | Q25: =VLOOKUP($J25,'mapping-Y26'!$M:$Q,7,0) -> #N/A | R25: =Q25/O25 -> #N/A | U25: 7.3 | X25: 1 | Z25: =T25*W25+U25*X25+V25*Y25 -> 7.3 | AA25: 0.1 | AB25: 0 | AC25: =Z25*(1-AA25-AB25)/1.13 -> 5.8141593 | AG25: =(R25-AD25)/R25 -> #N/A | AJ25: =(AH25+AI25)*AD25/R25+AG25 -> #N/A | AK25: =R25*(1-AJ25) -> #N/A | AL25: =VLOOKUP($J25,#REF!,12,0) -> #REF! | AM25: 0.027 | AN25: =AK25-R25*(AL25+AM25) -> #N/A | AO25: =AN25/AK25 -> #N/A | AQ25: =O25*AK25*AP25 -> #N/A | AR25: =AP25*AN25*O25 -> #N/A | AS25: =AP25*Q25 -> #N/A
A26: =F26&J26 -> 大润发南区2613-00 | D26: NKA | F26: 大润发南区 | G26: =VLOOKUP($J26,'mapping-Y26'!#REF!,2,0) -> #REF! | I26: =VLOOKUP($J26,'mapping-Y26'!$F:$L,5,0) -> 14004626 | J26: 2613-00 | K26: =VLOOKUP($J26,'mapping-Y26'!$F:$L,4,0) -> 261300舒洁无香湿巾单包装 | L26: =VLOOKUP($J26,'mapping-Y26'!#REF!,4,0) -> #REF! | M26: =VLOOKUP($J26,'mapping-Y26'!$H:$L,2,0) -> 261300舒洁无香湿巾单包装 | N26: =VLOOKUP($J26,'mapping-Y26'!M:N,3,0) -> #N/A | O26: =VLOOKUP($J26,'mapping-Y26'!$M:$N,5,0) -> #N/A | P26: =VLOOKUP($J26,'mapping-Y26'!$M:$N,6,0) -> #N/A | Q26: =VLOOKUP($J26,'mapping-Y26'!$M:$Q,7,0) -> #N/A | R26: =Q26/O26 -> #N/A | U26: 3.7 | X26: 1 | Z26: =T26*W26+U26*X26+V26*Y26 -> 3.7 | AA26: 0.1 | AB26: 0 | AC26: =Z26*(1-AA26-AB26)/1.13 -> 2.9469027 | AG26: =(R26-AD26)/R26 -> #N/A | AJ26: =(AH26+AI26)*AD26/R26+AG26 -> #N/A | AK26: =R26*(1-AJ26) -> #N/A | AL26: =VLOOKUP($J26,#REF!,12,0) -> #REF! | AM26: 0.027 | AN26: =AK26-R26*(AL26+AM26) -> #N/A | AO26: =AN26/AK26 -> #N/A | AQ26: =O26*AK26*AP26 -> #N/A | AR26: =AP26*AN26*O26 -> #N/A | AS26: =AP26*Q26 -> #N/A
A27: =F27&J27 -> 大润发东北区2694-50 | D27: NKA | F27: 大润发东北区 | G27: =VLOOKUP($J27,'mapping-Y26'!#REF!,2,0) -> #REF! | H27: =VLOOKUP($J27,'mapping-Y26'!$F:$L,6,0) -> 40P-55gsm | I27: =VLOOKUP($J27,'mapping-Y26'!$F:$L,5,0) -> 14017864 | J27: 2694-50 | K27: =VLOOKUP($J27,'mapping-Y26'!$F:$L,4,0) -> D269450舒洁湿厕纸家庭装40抽 | L27: =VLOOKUP($J27,'mapping-Y26'!#REF!,4,0) -> #REF! | M27: =VLOOKUP($J27,'mapping-Y26'!$H:$L,2,0) -> D269450舒洁湿厕纸家庭装40抽 | N27: =VLOOKUP($J27,'mapping-Y26'!M:N,3,0) -> #N/A | O27: =VLOOKUP($J27,'mapping-Y26'!$M:$N,5,0) -> #N/A | P27: =VLOOKUP($J27,'mapping-Y26'!$M:$N,6,0) -> #N/A | Q27: =VLOOKUP($J27,'mapping-Y26'!$M:$Q,7,0) -> #N/A | R27: =Q27/O27 -> #N/A | U27: 6.9 | X27: 1 | Z27: =T27*W27+U27*X27+V27*Y27 -> 6.9 | AA27: 0.1 | AB27: 0 | AC27: =Z27*(1-AA27-AB27)/1.13 -> 5.4955752 | AG27: =(R27-AD27)/R27 -> #N/A | AJ27: =(AH27+AI27)*AD27/R27+AG27 -> #N/A | AK27: =R27*(1-AJ27) -> #N/A | AL27: =VLOOKUP($J27,#REF!,12,0) -> #REF! | AM27: 0.027 | AN27: =AK27-R27*(AL27+AM27) -> #N/A | AO27: =AN27/AK27 -> #N/A | AQ27: =O27*AK27*AP27 -> #N/A | AR27: =AP27*AN27*O27 -> #N/A | AS27: =AP27*Q27 -> #N/A
A28: =F28&J28 -> 大润发东北区2673-00 | D28: NKA | F28: 大润发东北区 | G28: =VLOOKUP($J28,'mapping-Y26'!#REF!,2,0) -> #REF! | H28: =VLOOKUP($J28,'mapping-Y26'!$F:$L,6,0) -> 60P | I28: =VLOOKUP($J28,'mapping-Y26'!$F:$L,5,0) -> 14016683 | J28: 2673-00 | K28: =VLOOKUP($J28,'mapping-Y26'!$F:$L,4,0) -> 267300舒洁®山茶花系列湿巾（湿厕纸）60片 | L28: =VLOOKUP($J28,'mapping-Y26'!#REF!,4,0) -> #REF! | M28: =VLOOKUP($J28,'mapping-Y26'!$H:$L,2,0) -> 267300舒洁®山茶花系列湿巾（湿厕纸）60片 | N28: =VLOOKUP($J28,'mapping-Y26'!M:N,3,0) -> #N/A | O28: =VLOOKUP($J28,'mapping-Y26'!$M:$N,5,0) -> #N/A | P28: =VLOOKUP($J28,'mapping-Y26'!$M:$N,6,0) -> #N/A | Q28: =VLOOKUP($J28,'mapping-Y26'!$M:$Q,7,0) -> #N/A | R28: =Q28/O28 -> #N/A | U28: 8.9 | X28: 1 | Z28: =T28*W28+U28*X28+V28*Y28 -> 8.9 | AA28: 0.1 | AB28: 0 | AC28: =Z28*(1-AA28-AB28)/1.13 -> 7.0884956 | AG28: =(R28-AD28)/R28 -> #N/A | AJ28: =(AH28+AI28)*AD28/R28+AG28 -> #N/A | AK28: =R28*(1-AJ28) -> #N/A | AL28: =VLOOKUP($J28,#REF!,12,0) -> #REF! | AM28: 0.027 | AN28: =AK28-R28*(AL28+AM28) -> #N/A | AO28: =AN28/AK28 -> #N/A | AQ28: =O28*AK28*AP28 -> #N/A | AR28: =AP28*AN28*O28 -> #N/A | AS28: =AP28*Q28 -> #N/A
A29: =F29&J29 -> 大润发东北区2103-90 | D29: NKA | F29: 大润发东北区 | G29: =VLOOKUP($J29,'mapping-Y26'!#REF!,2,0) -> #REF! | I29: =VLOOKUP($J29,'mapping-Y26'!$F:$L,5,0) -> 14016868 | J29: 2103-90 | K29: =VLOOKUP($J29,'mapping-Y26'!$F:$L,4,0) -> 210390舒洁小熊印花抽纸3层80抽4包FSC mix70% | L29: =VLOOKUP($J29,'mapping-Y26'!#REF!,4,0) -> #REF! | M29: =VLOOKUP($J29,'mapping-Y26'!$H:$L,2,0) -> 210390舒洁小熊印花抽纸3层80抽4包FSC mix70% | N29: =VLOOKUP($J29,'mapping-Y26'!M:N,3,0) -> #N/A | O29: =VLOOKUP($J29,'mapping-Y26'!$M:$N,5,0) -> #N/A | P29: =VLOOKUP($J29,'mapping-Y26'!$M:$N,6,0) -> #N/A | Q29: =VLOOKUP($J29,'mapping-Y26'!$M:$Q,7,0) -> #N/A | R29: =Q29/O29 -> #N/A | U29: 12.8 | X29: 1 | Z29: =T29*W29+U29*X29+V29*Y29 -> 12.8 | AA29: 0.1 | AB29: 0 | AC29: =Z29*(1-AA29-AB29)/1.13 -> 10.19469 | AG29: =(R29-AD29)/R29 -> #N/A | AJ29: =(AH29+AI29)*AD29/R29+AG29 -> #N/A | AK29: =R29*(1-AJ29) -> #N/A | AL29: =VLOOKUP($J29,#REF!,12,0) -> #REF! | AM29: 0.027 | AN29: =AK29-R29*(AL29+AM29) -> #N/A | AO29: =AN29/AK29 -> #N/A | AQ29: =O29*AK29*AP29 -> #N/A | AR29: =AP29*AN29*O29 -> #N/A | AS29: =AP29*Q29 -> #N/A
A30: =F30&J30 -> 大润发东北区2701-90 | D30: NKA | F30: 大润发东北区 | G30: =VLOOKUP($J30,'mapping-Y26'!#REF!,2,0) -> #REF! | I30: =VLOOKUP($J30,'mapping-Y26'!$F:$L,5,0) -> 14016871 | J30: 2701-90 | K30: =VLOOKUP($J30,'mapping-Y26'!$F:$L,4,0) -> 270190舒洁小熊印花手帕纸3层10包FSC mix70% | L30: =VLOOKUP($J30,'mapping-Y26'!#REF!,4,0) -> #REF! | M30: =VLOOKUP($J30,'mapping-Y26'!$H:$L,2,0) -> 270190舒洁小熊印花手帕纸3层10包FSC mix70% | N30: =VLOOKUP($J30,'mapping-Y26'!M:N,3,0) -> #N/A | O30: =VLOOKUP($J30,'mapping-Y26'!$M:$N,5,0) -> #N/A | P30: =VLOOKUP($J30,'mapping-Y26'!$M:$N,6,0) -> #N/A | Q30: =VLOOKUP($J30,'mapping-Y26'!$M:$Q,7,0) -> #N/A | R30: =Q30/O30 -> #N/A | U30: 6.6 | X30: 1 | Z30: =T30*W30+U30*X30+V30*Y30 -> 6.6 | AA30: 0.1 | AB30: 0 | AC30: =Z30*(1-AA30-AB30)/1.13 -> 5.2566372 | AG30: =(R30-AD30)/R30 -> #N/A | AJ30: =(AH30+AI30)*AD30/R30+AG30 -> #N/A | AK30: =R30*(1-AJ30) -> #N/A | AL30: =VLOOKUP($J30,#REF!,12,0) -> #REF! | AM30: 0.027 | AN30: =AK30-R30*(AL30+AM30) -> #N/A | AO30: =AN30/AK30 -> #N/A | AQ30: =O30*AK30*AP30 -> #N/A | AR30: =AP30*AN30*O30 -> #N/A | AS30: =AP30*Q30 -> #N/A
A31: =F31&J31 -> 大润发华北区2660-10 | D31: NKA | F31: 大润发华北区 | G31: =VLOOKUP($J31,'mapping-Y26'!#REF!,2,0) -> #REF! | H31: =VLOOKUP($J31,'mapping-Y26'!$F:$L,6,0) -> 80P | I31: =VLOOKUP($J31,'mapping-Y26'!$F:$L,5,0) -> 14017865 | J31: 2660-10 | K31: =VLOOKUP($J31,'mapping-Y26'!$F:$L,4,0) -> 266010舒洁湿厕纸80片 | L31: =VLOOKUP($J31,'mapping-Y26'!#REF!,4,0) -> #REF! | M31: =VLOOKUP($J31,'mapping-Y26'!$H:$L,2,0) -> 266010舒洁湿厕纸80片 | N31: =VLOOKUP($J31,'mapping-Y26'!M:N,3,0) -> #N/A | O31: =VLOOKUP($J31,'mapping-Y26'!$M:$N,5,0) -> #N/A | P31: =VLOOKUP($J31,'mapping-Y26'!$M:$N,6,0) -> #N/A | Q31: =VLOOKUP($J31,'mapping-Y26'!$M:$Q,7,0) -> #N/A | R31: =Q31/O31 -> #N/A | U31: 10.9 | X31: 1 | Z31: =T31*W31+U31*X31+V31*Y31 -> 10.9 | AA31: 0.1 | AB31: 0 | AC31: =Z31*(1-AA31-AB31)/1.13 -> 8.6814159 | AG31: =(R31-AD31)/R31 -> #N/A | AJ31: =(AH31+AI31)*AD31/R31+AG31 -> #N/A | AK31: =R31*(1-AJ31) -> #N/A | AL31: =VLOOKUP($J31,#REF!,12,0) -> #REF! | AM31: 0.027 | AN31: =AK31-R31*(AL31+AM31) -> #N/A | AO31: =AN31/AK31 -> #N/A | AQ31: =O31*AK31*AP31 -> #N/A | AR31: =AP31*AN31*O31 -> #N/A | AS31: =AP31*Q31 -> #N/A
A32: =F32&J32 -> 大润发华北区2666-00 | D32: NKA | F32: 大润发华北区 | G32: =VLOOKUP($J32,'mapping-Y26'!#REF!,2,0) -> #REF! | I32: =VLOOKUP($J32,'mapping-Y26'!$F:$L,5,0) -> 14016486 | J32: 2666-00 | K32: =VLOOKUP($J32,'mapping-Y26'!$F:$L,4,0) -> 266600舒洁湿厕纸100片x6包 | L32: =VLOOKUP($J32,'mapping-Y26'!#REF!,4,0) -> #REF! | M32: =VLOOKUP($J32,'mapping-Y26'!$H:$L,2,0) -> 266600舒洁湿厕纸100片x6包 | N32: =VLOOKUP($J32,'mapping-Y26'!M:N,3,0) -> #N/A | O32: =VLOOKUP($J32,'mapping-Y26'!$M:$N,5,0) -> #N/A | P32: =VLOOKUP($J32,'mapping-Y26'!$M:$N,6,0) -> #N/A | Q32: =VLOOKUP($J32,'mapping-Y26'!$M:$Q,7,0) -> #N/A | R32: =Q32/O32 -> #N/A | U32: 14.9 | X32: 1 | Z32: =T32*W32+U32*X32+V32*Y32 -> 14.9 | AA32: 0.1 | AB32: 0 | AC32: =Z32*(1-AA32-AB32)/1.13 -> 11.867257 | AG32: =(R32-AD32)/R32 -> #N/A | AJ32: =(AH32+AI32)*AD32/R32+AG32 -> #N/A | AK32: =R32*(1-AJ32) -> #N/A | AL32: =VLOOKUP($J32,#REF!,12,0) -> #REF! | AM32: 0.027 | AN32: =AK32-R32*(AL32+AM32) -> #N/A | AO32: =AN32/AK32 -> #N/A | AQ32: =O32*AK32*AP32 -> #N/A | AR32: =AP32*AN32*O32 -> #N/A | AS32: =AP32*Q32 -> #N/A
A33: =F33&J33 -> 大润发华北区2155-03 | D33: NKA | F33: 大润发华北区 | G33: =VLOOKUP($J33,'mapping-Y26'!#REF!,2,0) -> #REF! | I33: =VLOOKUP($J33,'mapping-Y26'!$F:$L,5,0) -> 14016306 | J33: 2155-03 | K33: =VLOOKUP($J33,'mapping-Y26'!$F:$L,4,0) -> 215503舒洁®北海道轻牛乳系列乳霜纸面巾40抽3包装 | L33: =VLOOKUP($J33,'mapping-Y26'!#REF!,4,0) -> #REF! | M33: =VLOOKUP($J33,'mapping-Y26'!$H:$L,2,0) -> 215503舒洁®北海道轻牛乳系列乳霜纸面巾40抽3包装 | N33: =VLOOKUP($J33,'mapping-Y26'!M:N,3,0) -> #N/A | O33: =VLOOKUP($J33,'mapping-Y26'!$M:$N,5,0) -> #N/A | P33: =VLOOKUP($J33,'mapping-Y26'!$M:$N,6,0) -> #N/A | Q33: =VLOOKUP($J33,'mapping-Y26'!$M:$Q,7,0) -> #N/A | R33: =Q33/O33 -> #N/A | Z33: =T33*W33+U33*X33+V33*Y33 -> 0 | AA33: 0.1 | AB33: 0 | AC33: =Z33*(1-AA33-AB33)/1.13 -> 0 | AG33: =(R33-AD33)/R33 -> #N/A | AJ33: =(AH33+AI33)*AD33/R33+AG33 -> #N/A | AK33: =R33*(1-AJ33) -> #N/A | AL33: =VLOOKUP($J33,#REF!,12,0) -> #REF! | AM33: 0.027 | AN33: =AK33-R33*(AL33+AM33) -> #N/A | AO33: =AN33/AK33 -> #N/A | AQ33: =O33*AK33*AP33 -> #N/A | AR33: =AP33*AN33*O33 -> #N/A | AS33: =AP33*Q33 -> #N/A
A34: =F34&J34 -> 大润发华北区2162-08 | D34: NKA | F34: 大润发华北区 | G34: =VLOOKUP($J34,'mapping-Y26'!#REF!,2,0) -> #REF! | I34: =VLOOKUP($J34,'mapping-Y26'!$F:$L,5,0) -> 14015110 | J34: 2162-08 | K34: =VLOOKUP($J34,'mapping-Y26'!$F:$L,4,0) -> 216208舒洁®北海道牛乳系列乳霜纸面巾20抽8包装 | L34: =VLOOKUP($J34,'mapping-Y26'!#REF!,4,0) -> #REF! | M34: =VLOOKUP($J34,'mapping-Y26'!$H:$L,2,0) -> 216208舒洁®北海道牛乳系列乳霜纸面巾20抽8包装 | N34: =VLOOKUP($J34,'mapping-Y26'!M:N,3,0) -> #N/A | O34: =VLOOKUP($J34,'mapping-Y26'!$M:$N,5,0) -> #N/A | P34: =VLOOKUP($J34,'mapping-Y26'!$M:$N,6,0) -> #N/A | Q34: =VLOOKUP($J34,'mapping-Y26'!$M:$Q,7,0) -> #N/A | R34: =Q34/O34 -> #N/A | U34: 23.9 | X34: 1 | Z34: =T34*W34+U34*X34+V34*Y34 -> 23.9 | AA34: 0.1 | AB34: 0 | AC34: =Z34*(1-AA34-AB34)/1.13 -> 19.035398 | AG34: =(R34-AD34)/R34 -> #N/A | AJ34: =(AH34+AI34)*AD34/R34+AG34 -> #N/A | AK34: =R34*(1-AJ34) -> #N/A | AL34: =VLOOKUP($J34,#REF!,12,0) -> #REF! | AM34: 0.027 | AN34: =AK34-R34*(AL34+AM34) -> #N/A | AO34: =AN34/AK34 -> #N/A | AQ34: =O34*AK34*AP34 -> #N/A | AR34: =AP34*AN34*O34 -> #N/A | AS34: =AP34*Q34 -> #N/A
A35: =F35&J35 -> 大润发华北区2103-90 | D35: NKA | F35: 大润发华北区 | G35: =VLOOKUP($J35,'mapping-Y26'!#REF!,2,0) -> #REF! | I35: =VLOOKUP($J35,'mapping-Y26'!$F:$L,5,0) -> 14016868 | J35: 2103-90 | K35: =VLOOKUP($J35,'mapping-Y26'!$F:$L,4,0) -> 210390舒洁小熊印花抽纸3层80抽4包FSC mix70% | L35: =VLOOKUP($J35,'mapping-Y26'!#REF!,4,0) -> #REF! | M35: =VLOOKUP($J35,'mapping-Y26'!$H:$L,2,0) -> 210390舒洁小熊印花抽纸3层80抽4包FSC mix70% | N35: =VLOOKUP($J35,'mapping-Y26'!M:N,3,0) -> #N/A | O35: =VLOOKUP($J35,'mapping-Y26'!$M:$N,5,0) -> #N/A | P35: =VLOOKUP($J35,'mapping-Y26'!$M:$N,6,0) -> #N/A | Q35: =VLOOKUP($J35,'mapping-Y26'!$M:$Q,7,0) -> #N/A | R35: =Q35/O35 -> #N/A | U35: 13.9 | X35: 1 | Z35: =T35*W35+U35*X35+V35*Y35 -> 13.9 | AA35: 0.1 | AB35: 0 | AC35: =Z35*(1-AA35-AB35)/1.13 -> 11.070796 | AG35: =(R35-AD35)/R35 -> #N/A | AJ35: =(AH35+AI35)*AD35/R35+AG35 -> #N/A | AK35: =R35*(1-AJ35) -> #N/A | AL35: =VLOOKUP($J35,#REF!,12,0) -> #REF! | AM35: 0.027 | AN35: =AK35-R35*(AL35+AM35) -> #N/A | AO35: =AN35/AK35 -> #N/A | AQ35: =O35*AK35*AP35 -> #N/A | AR35: =AP35*AN35*O35 -> #N/A | AS35: =AP35*Q35 -> #N/A
A36: =F36&J36 -> 大润发华北区2107-61 | D36: NKA | F36: 大润发华北区 | G36: =VLOOKUP($J36,'mapping-Y26'!#REF!,2,0) -> #REF! | I36: =VLOOKUP($J36,'mapping-Y26'!$F:$L,5,0) -> 14014470 | J36: 2107-61 | K36: =VLOOKUP($J36,'mapping-Y26'!$F:$L,4,0) -> 210761舒洁卡通系列抽纸200抽3包 FSC mix70% | L36: =VLOOKUP($J36,'mapping-Y26'!#REF!,4,0) -> #REF! | M36: =VLOOKUP($J36,'mapping-Y26'!$H:$L,2,0) -> 210761舒洁卡通系列抽纸200抽3包 FSC mix70% | N36: =VLOOKUP($J36,'mapping-Y26'!M:N,3,0) -> #N/A | O36: =VLOOKUP($J36,'mapping-Y26'!$M:$N,5,0) -> #N/A | P36: =VLOOKUP($J36,'mapping-Y26'!$M:$N,6,0) -> #N/A | Q36: =VLOOKUP($J36,'mapping-Y26'!$M:$Q,7,0) -> #N/A | R36: =Q36/O36 -> #N/A | U36: 15.9 | X36: 1 | Z36: =T36*W36+U36*X36+V36*Y36 -> 15.9 | AA36: 0.1 | AB36: 0 | AC36: =Z36*(1-AA36-AB36)/1.13 -> 12.663717 | AG36: =(R36-AD36)/R36 -> #N/A | AJ36: =(AH36+AI36)*AD36/R36+AG36 -> #N/A | AK36: =R36*(1-AJ36) -> #N/A | AL36: =VLOOKUP($J36,#REF!,12,0) -> #REF! | AM36: 0.027 | AN36: =AK36-R36*(AL36+AM36) -> #N/A | AO36: =AN36/AK36 -> #N/A | AQ36: =O36*AK36*AP36 -> #N/A | AR36: =AP36*AN36*O36 -> #N/A | AS36: =AP36*Q36 -> #N/A
A37: =F37&J37 -> 大润发华北区2701-90 | D37: NKA | F37: 大润发华北区 | G37: =VLOOKUP($J37,'mapping-Y26'!#REF!,2,0) -> #REF! | I37: =VLOOKUP($J37,'mapping-Y26'!$F:$L,5,0) -> 14016871 | J37: 2701-90 | K37: =VLOOKUP($J37,'mapping-Y26'!$F:$L,4,0) -> 270190舒洁小熊印花手帕纸3层10包FSC mix70% | L37: =VLOOKUP($J37,'mapping-Y26'!#REF!,4,0) -> #REF! | M37: =VLOOKUP($J37,'mapping-Y26'!$H:$L,2,0) -> 270190舒洁小熊印花手帕纸3层10包FSC mix70% | N37: =VLOOKUP($J37,'mapping-Y26'!M:N,3,0) -> #N/A | O37: =VLOOKUP($J37,'mapping-Y26'!$M:$N,5,0) -> #N/A | P37: =VLOOKUP($J37,'mapping-Y26'!$M:$N,6,0) -> #N/A | Q37: =VLOOKUP($J37,'mapping-Y26'!$M:$Q,7,0) -> #N/A | R37: =Q37/O37 -> #N/A | U37: 6.9 | X37: 1 | Z37: =T37*W37+U37*X37+V37*Y37 -> 6.9 | AA37: 0.1 | AB37: 0 | AC37: =Z37*(1-AA37-AB37)/1.13 -> 5.4955752 | AG37: =(R37-AD37)/R37 -> #N/A | AJ37: =(AH37+AI37)*AD37/R37+AG37 -> #N/A | AK37: =R37*(1-AJ37) -> #N/A | AL37: =VLOOKUP($J37,#REF!,12,0) -> #REF! | AM37: 0.027 | AN37: =AK37-R37*(AL37+AM37) -> #N/A | AO37: =AN37/AK37 -> #N/A | AQ37: =O37*AK37*AP37 -> #N/A | AR37: =AP37*AN37*O37 -> #N/A | AS37: =AP37*Q37 -> #N/A
A38: =F38&J38 -> Hema2660-10 | D38: NKA | F38: Hema | G38: =VLOOKUP($J38,'mapping-Y26'!#REF!,2,0) -> #REF! | H38: =VLOOKUP($J38,'mapping-Y26'!$F:$L,6,0) -> 80P | I38: =VLOOKUP($J38,'mapping-Y26'!$F:$L,5,0) -> 14017865 | J38: 2660-10 | K38: =VLOOKUP($J38,'mapping-Y26'!$F:$L,4,0) -> 266010舒洁湿厕纸80片 | L38: =VLOOKUP($J38,'mapping-Y26'!#REF!,4,0) -> #REF! | M38: =VLOOKUP($J38,'mapping-Y26'!$H:$L,2,0) -> 266010舒洁湿厕纸80片 | N38: =VLOOKUP($J38,'mapping-Y26'!M:N,3,0) -> #N/A | O38: =VLOOKUP($J38,'mapping-Y26'!$M:$N,5,0) -> #N/A | P38: =VLOOKUP($J38,'mapping-Y26'!$M:$N,6,0) -> #N/A | Q38: =VLOOKUP($J38,'mapping-Y26'!$M:$Q,7,0) -> #N/A | R38: =Q38/O38 -> #N/A | U38: 14.9 | X38: 1 | Z38: =T38*W38+U38*X38+V38*Y38 -> 14.9 | AA38: 0.36845638 | AB38: 0 | AC38: =Z38*(1-AA38-AB38)/1.13 -> 8.3274336 | AG38: =(R38-AD38)/R38 -> #N/A | AJ38: =(AH38+AI38)*AD38/R38+AG38 -> #N/A | AK38: =R38*(1-AJ38) -> #N/A | AL38: =VLOOKUP($J38,#REF!,12,0) -> #REF! | AM38: 0.027 | AN38: =AK38-R38*(AL38+AM38) -> #N/A | AO38: =AN38/AK38 -> #N/A | AQ38: =O38*AK38*AP38 -> #N/A | AR38: =AP38*AN38*O38 -> #N/A | AS38: =AP38*Q38 -> #N/A
A39: =F39&J39 -> Hema2661-10 | D39: NKA | F39: Hema | G39: =VLOOKUP($J39,'mapping-Y26'!#REF!,2,0) -> #REF! | H39: =VLOOKUP($J39,'mapping-Y26'!$F:$L,6,0) -> 80P-55gsm | I39: =VLOOKUP($J39,'mapping-Y26'!$F:$L,5,0) -> 14017866 | J39: 2661-10 | K39: =VLOOKUP($J39,'mapping-Y26'!$F:$L,4,0) -> 266110舒洁湿厕纸80片x3包 | L39: =VLOOKUP($J39,'mapping-Y26'!#REF!,4,0) -> #REF! | M39: =VLOOKUP($J39,'mapping-Y26'!$H:$L,2,0) -> 266110舒洁湿厕纸80片x3包 | N39: =VLOOKUP($J39,'mapping-Y26'!M:N,3,0) -> #N/A | O39: =VLOOKUP($J39,'mapping-Y26'!$M:$N,5,0) -> #N/A | P39: =VLOOKUP($J39,'mapping-Y26'!$M:$N,6,0) -> #N/A | Q39: =VLOOKUP($J39,'mapping-Y26'!$M:$Q,7,0) -> #N/A | R39: =Q39/O39 -> #N/A | U39: 33.9 | X39: 1 | Z39: =T39*W39+U39*X39+V39*Y39 -> 33.9 | AA39: 0.25006143 | AB39: 0 | AC39: =Z39*(1-AA39-AB39)/1.13 -> 22.498157 | AG39: =(R39-AD39)/R39 -> #N/A | AJ39: =(AH39+AI39)*AD39/R39+AG39 -> #N/A | AK39: =R39*(1-AJ39) -> #N/A | AL39: =VLOOKUP($J39,#REF!,12,0) -> #REF! | AM39: 0.027 | AN39: =AK39-R39*(AL39+AM39) -> #N/A | AO39: =AN39/AK39 -> #N/A | AQ39: =O39*AK39*AP39 -> #N/A | AR39: =AP39*AN39*O39 -> #N/A | AS39: =AP39*Q39 -> #N/A
A40: =F40&J40 -> Hema2670-40 | D40: NKA | F40: Hema | G40: =VLOOKUP($J40,'mapping-Y26'!#REF!,2,0) -> #REF! | H40: =VLOOKUP($J40,'mapping-Y26'!$F:$L,6,0) -> 10P-55gsm | I40: =VLOOKUP($J40,'mapping-Y26'!$F:$L,5,0) -> 14017871 | J40: 2670-40 | K40: =VLOOKUP($J40,'mapping-Y26'!$F:$L,4,0) -> D267040舒洁湿厕纸旅行装10包装 | L40: =VLOOKUP($J40,'mapping-Y26'!#REF!,4,0) -> #REF! | M40: =VLOOKUP($J40,'mapping-Y26'!$H:$L,2,0) -> D267040舒洁湿厕纸旅行装10包装 | N40: =VLOOKUP($J40,'mapping-Y26'!M:N,3,0) -> #N/A | O40: =VLOOKUP($J40,'mapping-Y26'!$M:$N,5,0) -> #N/A | P40: =VLOOKUP($J40,'mapping-Y26'!$M:$N,6,0) -> #N/A | Q40: =VLOOKUP($J40,'mapping-Y26'!$M:$Q,7,0) -> #N/A | R40: =Q40/O40 -> #N/A | U40: 21.9 | X40: 1 | Z40: =T40*W40+U40*X40+V40*Y40 -> 21.9 | AA40: 0.18 | AB40: 0 | AC40: =Z40*(1-AA40-AB40)/1.13 -> 15.892035 | AG40: =(R40-AD40)/R40 -> #N/A | AJ40: =(AH40+AI40)*AD40/R40+AG40 -> #N/A | AK40: =R40*(1-AJ40) -> #N/A | AL40: =VLOOKUP($J40,#REF!,12,0) -> #REF! | AM40: 0.027 | AN40: =AK40-R40*(AL40+AM40) -> #N/A | AO40: =AN40/AK40 -> #N/A | AQ40: =O40*AK40*AP40 -> #N/A | AR40: =AP40*AN40*O40 -> #N/A | AS40: =AP40*Q40 -> #N/A
...

Sheet mapping-Y26
B1: category | C1: 产品系列 | D1: fcst line | E1: 4 PRO | F1: Merge_code | G1: Barcode（EA） | H1: pro code | I1: Description | J1: sap code | K1: Size | L1: PR00 Price | M1: EA/Case | N1: Pack/EA | O1: PR00 Price
B2: FMC | C2: =VLOOKUP(F2,[1]Assortment!$F:$AS,27,0) -> 抽纸 | D2: Box Facial | E2: 2312 | F2: 2312-16 | G2: 6923589423128 | H2: 2312-16 | I2: =VLOOKUP(H2,[2]FMC!$A:$D,4,0) -> 231216 舒洁马蹄莲盒面纸200抽3盒 FSC mix70% | J2: 14014482 | K2: # | L2: 243.21307 | M2: 10 | N2: 3 | O2: 243.21307
B3: FMC | C3: =VLOOKUP(F3,[1]Assortment!$F:$AS,27,0) -> 手帕纸 | D3: Hanky | E3: 2701 | F3: 2701-90 | G3: 6923589427010 | H3: 2701-90 | I3: =VLOOKUP(H3,[2]FMC!$A:$D,4,0) -> 270190舒洁小熊印花手帕纸3层10包FSC mix70% | J3: 14016871 | K3: # | L3: 208.46834 | M3: 36 | N3: 10 | O3: 208.46834
B4: FMC | C4: =VLOOKUP(F4,[1]Assortment!$F:$AS,27,0) -> 抽纸 | D4: Poly Facial | E4: 2103 | F4: 2103-90 | G4: 6923589421032 | H4: 2103-90 | I4: =VLOOKUP(H4,[2]FMC!$A:$D,4,0) -> 210390舒洁小熊印花抽纸3层80抽4包FSC mix70% | J4: 14016868 | K4: # | L4: 287.22305 | M4: 24 | N4: 4 | O4: 287.22305
B5: FMC | C5: =VLOOKUP(F5,[1]Assortment!$F:$AS,27,0) -> 抽纸 | D5: Poly Facial | E5: 2107 | F5: 2107-61 | G5: 6923589421070 | H5: 2107-61 | I5: =VLOOKUP(H5,[2]FMC!$A:$D,4,0) -> 210761舒洁卡通系列抽纸200抽3包 FSC mix70% | J5: 14014470 | K5: # | L5: 338.18199 | M5: 20 | N5: 3 | O5: 338.18199
B6: FMC | C6: =VLOOKUP(F6,[1]Assortment!$F:$AS,27,0) -> 抽纸 | D6: Poly Facial | E6: 2148 | F6: 2148-90 | G6: 6923589421483 | H6: 2148-90 | I6: =VLOOKUP(H6,[2]FMC!$A:$D,4,0) -> 214890舒洁小熊印花抽纸3层80抽16包FSC mix70% | J6: 14016869 | K6: # | L6: 283.80123 | M6: 6 | N6: 16 | O6: 283.80123
B7: FMC | C7: =VLOOKUP(F7,[1]Assortment!$F:$AS,27,0) -> 乳霜纸 | D7: Poly Facial | E7: 2152 | F7: 2152-04 | G7: 6923589421520 | H7: 2152-04 | I7: =VLOOKUP(H7,[2]FMC!$A:$D,4,0) -> 215204舒洁鎏金系列乳霜纸巾40抽8包 | J7: 14014940 | K7: Lotion 3Ply | L7: 105.788 | M7: 4 | N7: 8 | O7: 105.788
B8: FMC | C8: =VLOOKUP(F8,[1]Assortment!$F:$AS,27,0) -> 乳霜纸 | D8: Poly Facial | E8: 2155 | F8: 2155-03 | G8: 6923589421551 | H8: 2155-03 | I8: =VLOOKUP(H8,[2]FMC!$A:$D,4,0) -> 215503舒洁®北海道轻牛乳系列乳霜纸面巾40抽3包装 | J8: 14016306 | K8: Lotion 4Ply | L8: 222.4 | M8: 16 | N8: 3 | O8: 222.4
B9: FMC | C9: =VLOOKUP(F9,[1]Assortment!$F:$AS,27,0) -> 乳霜纸 | D9: Poly Facial | E9: 2156 | F9: 2156-10 | G9: 6923589421568 | H9: 2156-10 | I9: =VLOOKUP(H9,[2]FMC!$A:$D,4,0) -> 215610舒洁®北海道轻牛乳系列乳霜纸面巾100抽3包装 | J9: 14016307 | K9: Lotion 4Ply | L9: 215.4 | M9: 6 | N9: 3 | O9: 215.4
B10: FMC | C10: =VLOOKUP(F10,[1]Assortment!$F:$AS,27,0) -> 乳霜纸 | D10: Poly Facial | E10: 2162 | F10: 2162-08 | G10: 6923589421629 | H10: 2162-08 | I10: =VLOOKUP(H10,[2]FMC!$A:$D,4,0) -> 216208舒洁®北海道牛乳系列乳霜纸面巾20抽8包装 | J10: 14015110 | K10: Lotion 6Ply | L10: 100.4986 | M10: 4 | N10: 8 | O10: 100.4986
B11: FMC | C11: =VLOOKUP(F11,[1]Assortment!$F:$AS,27,0) -> 乳霜纸 | D11: Poly Facial | E11: 2167 | F11: 2167-10 | G11: 6923589421605 | H11: 2167-10 | I11: =VLOOKUP(H11,[2]FMC!$A:$D,4,0) -> 216710舒洁®牛乳系列乳霜纸面巾口袋包7抽10包装 | J11: 14016042 | K11: Lotion 6Ply | L11: 202.8 | M11: 12 | N11: 10 | O11: 202.8
B12: FMC | C12: =VLOOKUP(F12,[1]Assortment!$F:$AS,27,0) -> 乳霜纸 | D12: Poly Facial | E12: 2168 | F12: 2168-05 | G12: 6923589421681 | H12: 2168-05 | I12: =VLOOKUP(H12,[2]FMC!$A:$D,4,0) -> 216805舒洁®北海道牛乳系列乳霜纸面巾80抽5包装 | J12: 14015111 | K12: Lotion 6Ply | L12: 215.568 | M12: 3 | N12: 5 | O12: 215.568
B13: FMC | C13: =VLOOKUP(F13,[1]Assortment!$F:$AS,27,0) -> 乳霜纸 | D13: Poly Facial | E13: 2168-00 | F13: 2168-00 | G13: 6923589421681 | H13: 2168-00 | I13: 216800舒洁®北海道牛乳系列乳霜纸面巾80抽5包装（山姆） | J13: 14018015 | K13: Lotion 6Ply | L13: 431.136 | M13: 6 | N13: 5 | O13: 431.136
A14: 山姆专供 | B14: FMC | C14: =VLOOKUP(F14,[1]Assortment!$F:$AS,27,0) -> 乳霜纸 | D14: Poly Facial | E14: 2169 | F14: 2169-00 | G14: 6923589421704 | H14: 2169-00 | I14: =VLOOKUP(H14,[2]FMC!$A:$D,4,0) -> 216900舒洁®北海道牛乳系列乳霜纸面巾80抽6包装 | J14: 14018125 | K14: Lotion 6Ply-山姆 | L14: 431.136 | M14: 6 | N14: 6 | O14: 431.136
B15: FMC | C15: =VLOOKUP(F15,[1]Assortment!$F:$AS,27,0) -> 湿厕纸 | D15: Wet Wipes | E15: 2613 | F15: 2613-00 | G15: 6923589426136 | H15: 2613-00 | I15: =VLOOKUP(H15,[2]FMC!$A:$D,4,0) -> 261300舒洁无香湿巾单包装 | J15: 14004626 | K15: # | L15: 91.36283 | M15: 30 | N15: 1 | O15: 91.36283
B16: FMC | C16: =VLOOKUP(F16,[1]Assortment!$F:$AS,27,0) -> 洗脸巾 | D16: Dry Wipes | E16: 2530 | F16: 2530-00 | G16: 6923589425306 | H16: 2530-00 | I16: =VLOOKUP(H16,[2]FMC!$A:$D,4,0) -> 253000舒洁蚕丝洗脸巾80抽3包装 | J16: 14015043 | K16: # | L16: 358.2 | M16: 6 | N16: 3 | O16: 358.2
B17: FMC | C17: =VLOOKUP(F17,[1]Assortment!$F:$AS,27,0) -> 湿厕纸 | D17: MBT | E17: 2655 | F17: 2655-10 | G17: 6923589426556 | H17: 2655-10 | I17: =VLOOKUP(H17,[2]FMC!$A:$D,4,0) -> 265510舒洁湿厕纸7抽6包装 | J17: 14017863 | K17: 7P-55gsm | L17: 179.2 | M17: 16 | N17: 6 | O17: 179.2
B18: FMC | C18: =VLOOKUP(F18,[1]Assortment!$F:$AS,27,0) -> 湿厕纸 | D18: MBT | E18: 2608 | F18: 2608-00 | G18: 6923589426082 | H18: 2608-00 | I18: =VLOOKUP(H18,[2]FMC!$A:$D,4,0) -> 260800舒洁湿厕纸(65gsm)7抽6包装 | J18: 14018368 | K18: 7P-65gsm | L18: 179.2 | M18: 16 | N18: 6 | O18: 179.2
A19: 山姆专供 | B19: FMC | C19: =VLOOKUP(F19,[1]Assortment!$F:$AS,27,0) -> 湿厕纸 | D19: MBT | E19: 2609 | F19: 2609-00 | G19: 6923589426099 | H19: 2609-00 | I19: =VLOOKUP(H19,[2]FMC!$A:$D,4,0) -> 260900舒洁湿厕纸(65gsm)8片x48包 | J19: 14018377 | K19: 8P-65gsm-山姆 | L19: 102.4 | M19: 1 | N19: 48 | O19: 102.4
B20: FMC | C20: =VLOOKUP(F20,[1]Assortment!$F:$AS,27,0) -> 湿厕纸 | D20: MBT | E20: 2670 | F20: 2670-40 | G20: 6923589426709 | H20: 2670-40 | I20: =VLOOKUP(H20,[2]FMC!$A:$D,4,0) -> D267040舒洁湿厕纸旅行装10包装 | J20: 14017871 | K20: 10P-55gsm | L20: 151.33 | M20: 4 | N20: 10 | O20: 151.33
B21: FMC | C21: =VLOOKUP(F21,[1]Assortment!$F:$AS,27,0) -> 湿厕纸 | D21: MBT | E21: 2610 | F21: 2610-00 | G21: 6923589426105 | H21: 2610-00 | I21: =VLOOKUP(H21,[2]FMC!$A:$D,4,0) -> 261000舒洁湿厕纸(65gsm)旅行装10片x10包装 | J21: 14018369 | K21: 10P-65gsm | L21: 151.33 | M21: 4 | N21: 10 | O21: 151.33
B22: FMC | C22: =VLOOKUP(F22,[1]Assortment!$F:$AS,27,0) -> 湿厕纸 | D22: MBT | E22: 2682 | F22: 2682-20 | G22: 6923589426822 | H22: 2682-20 | I22: =VLOOKUP(H22,[2]FMC!$A:$D,4,0) -> 268220舒洁女性湿厕纸10包装 | J22: 14014250 | K22: 24P | L22: 255.40531 | M22: 4 | N22: 10 | O22: 255.40531
B23: FMC | C23: =VLOOKUP(F23,[1]Assortment!$F:$AS,27,0) -> 湿厕纸 | D23: MBT | E23: 2694 | F23: 2694-30 | G23: 6923589426945 | H23: 2694-30 | I23: =VLOOKUP(H23,[2]FMC!$A:$D,4,0) -> D269430舒洁湿厕纸家庭装40抽 | J23: 14014247 | K23: 40P-55gsm | L23: 367.52 | M23: 40 | N23: 1 | O23: 367.52197
B24: FMC | C24: =VLOOKUP(F24,[1]Assortment!$F:$AS,27,0) -> 湿厕纸 | D24: MBT | E24: 2694 | F24: 2694-50 | G24: 6923589426945 | H24: 2694-50 | I24: =VLOOKUP(H24,[2]FMC!$A:$D,4,0) -> D269450舒洁湿厕纸家庭装40抽 | J24: 14017864 | K24: 40P-55gsm | L24: 367.52 | M24: 40 | N24: 1 | O24: 367.52
B25: FMC | C25: =VLOOKUP(F25,[1]Assortment!$F:$AS,27,0) -> 湿厕纸 | D25: MBT | E25: 2620 | F25: 2620-00 | G25: 6923589426204 | H25: 2620-00 | I25: =VLOOKUP(H25,[2]FMC!$A:$D,4,0) -> 262000舒洁湿厕纸(65gsm)家庭装40抽 | J25: 14018370 | K25: 40P-65gsm | L25: 367.52 | M25: 40 | N25: 1 | O25: 367.52
B26: FMC | C26: =VLOOKUP(F26,[1]Assortment!$F:$AS,27,0) -> 湿厕纸 | D26: MBT | E26: 2694 | F26: 2694-60 | G26: 6923589420011 | H26: 2694-60 | I26: =VLOOKUP(H26,[2]FMC!$A:$D,4,0) -> D269460舒洁湿厕纸家庭装40抽10包装 | J26: 14017872 | K26: 40P-55gsm | L26: 330.25 | M26: 4 | N26: 10 | O26: 330.25
B27: FMC | C27: =VLOOKUP(F27,[1]Assortment!$F:$AS,27,0) -> 湿厕纸 | D27: MBT | E27: 2624 | F27: 2624-00 | G27: 6923589426242 | H27: 2624-00 | I27: =VLOOKUP(H27,[2]FMC!$A:$D,4,0) -> 262400舒洁湿厕纸(65gsm)家庭装40抽10包装 | J27: 14018371 | K27: 40P-65gsm | L27: 330.25 | M27: 4 | N27: 10 | O27: 330.25
B28: FMC | C28: =VLOOKUP(F28,[1]Assortment!$F:$AS,27,0) -> 湿厕纸 | D28: MBT | E28: 2673 | F28: 2673-00 | G28: 6923589426730 | H28: 2673-00 | I28: =VLOOKUP(H28,[2]FMC!$A:$D,4,0) -> 267300舒洁®山茶花系列湿巾（湿厕纸）60片 | J28: 14016683 | K28: 60P | L28: 244.8 | M28: 24 | N28: 1 | O28: 244.8
B29: FMC | C29: =VLOOKUP(F29,[1]Assortment!$F:$AS,27,0) -> 湿厕纸 | D29: MBT | E29: 2674 | F29: 2674-00 | G29: 6923589426730 | H29: 2674-00 | I29: =VLOOKUP(H29,[2]FMC!$A:$D,4,0) -> 267400舒洁®山茶花系列湿巾（湿厕纸）60片x4包 | J29: 14016684 | K29: 60P | L29: 41.9 | M29: 1 | N29: 4 | O29: 41.9
B30: FMC | C30: =VLOOKUP(F30,[1]Assortment!$F:$AS,27,0) -> 湿厕纸 | D30: MBT | E30: 2660 | F30: 2660-10 | G30: 6923589426600 | H30: 2660-10 | I30: =VLOOKUP(H30,[2]FMC!$A:$D,4,0) -> 266010舒洁湿厕纸80片 | J30: 14017865 | K30: 80P | L30: 326.88 | M30: 24 | N30: 1 | O30: 326.88
B31: FMC | C31: =VLOOKUP(F31,[1]Assortment!$F:$AS,27,0) -> 湿厕纸 | D31: MBT | E31: 2634 | F31: 2634-00 | G31: 6923589426341 | H31: 2634-00 | I31: =VLOOKUP(H31,[2]FMC!$A:$D,4,0) -> 263400舒洁湿厕纸(65gsm)80片 | J31: 14018372 | K31: 80P-55gsm | L31: 326.88 | M31: 24 | N31: 1 | O31: 326.88
... B33: FMC | C33: =VLOOKUP(F33,[1]Assortment!$F:$AS,27,0) -> 湿厕纸 | D33: MBT | E33: 2661 | F33: 2661-10 | G33: 6923589426617 | H33: 2661-10 | I33: =VLOOKUP(H33,[2]FMC!$A:$D,4,0) -> 266110舒洁湿厕纸80片x3包 | J33: 14017866 | K33: 80P-55gsm | L33: 310.48 | M33: 8 | N33: 3 | O33: 310.48
B34: FMC | C34: 湿厕纸 | D34: MBT | E34: 2635 | F34: 2635-00 | G34: 6923589426358 | H34: 2635-00 | I34: =VLOOKUP(H34,[2]FMC!$A:$D,4,0) -> 263500舒洁湿厕纸(65gsm)80片x3包 | J34: 14018373 | K34: 80P-65gsm | L34: 310.48 | M34: 8 | N34: 3 | O34: 310.48
B35: FMC | C35: =VLOOKUP(F35,[1]Assortment!$F:$AS,27,0) -> 湿厕纸 | D35: MBT | E35: 2662 | F35: 2662-10 | G35: 6923589426624 | H35: 2662-10 | I35: =VLOOKUP(H35,[2]FMC!$A:$D,4,0) -> 266210舒洁湿厕纸80片x6包 | J35: 14017868 | K35: 80P | L35: 69.44 | M35: 1 | N35: 6 | O35: 69.44
B36: FMC | C36: =VLOOKUP(F36,[1]Assortment!$F:$AS,27,0) -> 湿厕纸 | D36: MBT | E36: 2636 | F36: 2636-00 | G36: 6923589426365 | H36: 2636-00 | I36: =VLOOKUP(H36,[2]FMC!$A:$D,4,0) -> 263600舒洁湿厕纸(65gsm)80片x6包 | J36: 14018374 | K36: 80P-65gsm | L36: 69.44 | M36: 1 | N36: 6 | O36: 69.44
B37: FMC | C37: =VLOOKUP(F37,[1]Assortment!$F:$AS,27,0) -> 湿厕纸 | D37: MBT | E37: 2664 | F37: 2664-10 | G37: 6923589426600 | H37: 2664-10 | I37: =VLOOKUP(H37,[2]FMC!$A:$D,4,0) -> 266410舒洁湿厕纸80片x8包(黄箱) | J37: 14017869 | K37: 80P-55gsm | L37: 92.6 | M37: 1 | N37: 8 | O37: 92.6
B38: FMC | C38: 湿厕纸 | D38: MBT | E38: 2637 | F38: 2637-00 | G38: 6923589426372 | H38: 2637-00 | I38: =VLOOKUP(H38,[2]FMC!$A:$D,4,0) -> 263700舒洁湿厕纸(65gsm)80片x8包 | J38: 14018375 | K38: 80P-65gsm | L38: 92.6 | M38: 1 | N38: 8 | O38: 92.6
B39: FMC | C39: 湿厕纸 | D39: MBT | E39: 2665 | F39: 2665-10 | G39: 6923589426600 | H39: 2665-10 | I39: =VLOOKUP(H39,[2]FMC!$A:$D,4,0) -> D266510舒洁湿厕纸80片x10包-京东 | J39: 14017870 | K39: 80P-55gsm | L39: 115.7 | M39: 1 | N39: 10 | O39: 115.7
B40: FMC | C40: 湿厕纸 | D40: MBT | E40: 2638 | F40: 2638-00 | G40: 6923589426389 | H40: 2638-00 | I40: =VLOOKUP(H40,[2]FMC!$A:$D,4,0) -> 263800舒洁湿厕纸(65gsm)80片x10包 | J40: 14018376 | K40: 80P-65gsm | L40: 115.7 | M40: 1 | N40: 10 | O40: 115.7
B41: FMC | C41: =VLOOKUP(F41,[1]Assortment!$F:$AS,27,0) -> 湿厕纸 | D41: MBT | E41: 2666 | F41: 2666-00 | G41: 6923589426662 | H41: 2666-00 | I41: =VLOOKUP(H41,[2]FMC!$A:$D,4,0) -> 266600舒洁湿厕纸100片x6包 | J41: 14016486 | K41: 100P | L41: 86.8 | M41: 1 | N41: 1 | O41: 86.8
...

Sheet Sheet2
A2: CVS | B2: 全家
A3: CVS | B3: 罗森
A4: CVS | B4: 711
A5: CVS-Others | B5: 便利蜂
A6: CVS-Others | B6: 美宜佳
A7: CVS-Others | B7: 十足
A8: CVS-Others | B8: 唐久便利店
A9: CVS-Others | B9: 金虎便利店
A10: CVS-Others | B10: 芙蓉兴盛
A11: CVS-Others | B11: 左邻右舍
A12: NKA | B12: 大润发
A13: NKA | B13: 盒马
A14: NKA | B14: 麦德龙
A15: NKA | B15: 永辉
A16: NKA | B16: 山姆
... A54: RLKA | B54: 易初莲花

Sheet 26年价格体系T1
B1: 销售填写 | C1: 销售填写 | D1: 公式 | E1: 公式 | F1: 公式 | G1: 公式 | H1: 公式 | I1: KA填写 | J1: =SUM(J3:J26) -> 78.541439 | K1: =SUM(K3:K26) -> 88.751826 | N1: =SUM(N3:N26) -> 87.885939 | O1: =SUM(O3:O26) -> 90.522518 | P1: =SUM(P3:P26) -> 77.775168 | R1: =SUM(R3:R26) -> 90.517718 | S1: 不填 | T1: 不填 | U1: 不填 | V1: 公式 | W1: 公式 | X1: 公式 | Y1: 公式 | Z1: 参照O列 | AA1: 参照O列 | AC1: 参照P列 | AD1: 参照O列 | AE1: 参照O列 | AI1: EDLP | AJ1: EDLP
B2: 客户 | C2: Product Code | D2: 产品名称 | E2: 箱规 | F2: 包/箱 | G2: PR00 (箱价)-未税 | H2: PR00/EA | I2: 进货箱数 | J2: 中提供台参考nsv价格 | K2: 1.13含税 | L2: 经销商实际到手价格@ Shengtao | M2: 经销商打款价格（3返利%） | N2: 客户实际含税到手价格 | O2: 剔除3%返利（客户打款含税价格） | P2: nsv实际需要价格 | Q2: 实际需求与指引差 | R2: 打款价格/包-含税 | S2: 后补/包-含税 | T2: 后补金额-含税-TTL | U2: 后补金额未税-TTL | V2: GSV | W2: NSV | X2: DQF COGS % VS GSV | Y2: DQF DE % VS GSV | Z2: GP | AA2: GP% | AC2: NSV | AD2: GP | AE2: GP%（我们Propose） | AF2: Biz.Weight-2025 | AG2: Biz.Weight-2026-Proposal-@ Shengtao | AI2: 含票扣3.4%箱价 /不含税 | AJ2: 维护折扣金额-1000箱 | AK2: Sales Quantity CS | AL2: GSV
B3: T1级 | C3: 2701-90 | D3: =VLOOKUP($C3,[1]Assortment!$F:$BA,5,0) -> 270190舒洁小熊印花手帕纸3层10包FSC mix70% | E3: =VLOOKUP($C3,[1]Assortment!$F:$AM,7,0) -> 36 | F3: =VLOOKUP($C3,[1]Assortment!$F:$AM,31,0) -> 360 | G3: =VLOOKUP($C3,[1]Assortment!$F:$AM,14,0) -> 208.46834 | H3: =G3/E3 -> 5.7907872 | I3: 1 | J3: 0.38649421 | K3: =J3*1.13 -> 0.43673846 | L3: 0.39 | M3: =L3*1.03 -> 0.4017 | N3: 0.39 | O3: =N3*1.03 -> 0.4017 | P3: =N3/1.13 -> 0.34513274 | Q3: =P3-J3 -> -0.041361471 | R3: =O3 -> 0.4017 | V3: =G3*I3 -> 208.46834 | W3: =R3*F3*I3/1.13 -> 127.97522 | X3: ='25年版cogs'!F4 -> 0.42397103 | Y3: ='25年版cogs'!G4 -> 0.025426167 | Z3: =W3-V3*(X3+Y3) -> 34.290133 | AA3: =Z3/W3 -> 0.26794354 | AC3: =P3*F3*I3 -> 124.24779 | AD3: =AC3-V3*(X3+Y3) -> 30.5627 | AE3: =AD3/AC3 -> 0.24598184 | AF3: 0.027504779 | AG3: 0.018 | AH3: =SUM(AG3:AG26) -> 0.99974101 | AI3: =R3*F3/0.966/1.13 -> 132.47953 | AJ3: =(G3-AI3)*1000 -> 75988.815 | AK3: 1.341 | AL3: =AK3*G3 -> 279.55604
B4: T1级 | C4: 2694-40 | D4: =VLOOKUP($C4,[1]Assortment!$F:$BA,5,0) -> 269440舒洁湿厕纸家庭装40抽10包装 | E4: =VLOOKUP($C4,[1]Assortment!$F:$AM,7,0) -> 4 | F4: =VLOOKUP($C4,[1]Assortment!$F:$AM,31,0) -> 40 | G4: =VLOOKUP($C4,[1]Assortment!$F:$AM,14,0) -> 330.25 | H4: =G4/E4 -> 82.5625 | I4: 1 | J4: 2.7785183 | K4: =J4*1.13 -> 3.1397256 | L4: 3.65 | M4: =L4*1.03 -> 3.7595 | N4: 3.65 | O4: =N4*1.03 -> 3.7595 | P4: =N4/1.13 -> 3.2300885 | Q4: =P4-J4 -> 0.45157023 | R4: =O4 -> 3.7595 | V4: =G4*I4 -> 330.25 | W4: =R4*F4*I4/1.13 -> 133.07965 | X4: ='25年版cogs'!F5 -> 0.26981474 | Y4: ='25年版cogs'!G5 -> 0.025386209 | Z4: =W4-V4*(X4+Y4) -> 35.589534 | AA4: =Z4/W4 -> 0.26743033 | AC4: =P4*F4*I4 -> 129.20354 | AD4: =AC4-V4*(X4+Y4) -> 31.713428 | AE4: =AD4/AC4 -> 0.24545324 | AF4: 0.052241538 | AG4: 0.04 | AK4: 2.617 | AL4: =AK4*G4 -> 864.26425
B5: T1级 | C5: 2694-30 | D5: =VLOOKUP($C5,[1]Assortment!$F:$BA,5,0) -> 269430舒洁湿厕纸家庭装40抽 | E5: =VLOOKUP($C5,[1]Assortment!$F:$AM,7,0) -> 40 | F5: =VLOOKUP($C5,[1]Assortment!$F:$AM,31,0) -> 40 | G5: =VLOOKUP($C5,[1]Assortment!$F:$AM,14,0) -> 367.52 | H5: =G5/E5 -> 9.188 | I5: 1 | J5: 3.5557967 | K5: =J5*1.13 -> 4.0180503 | L5: 3.6 | M5: =L5*1.03 -> 3.708 | N5: 3.6 | O5: =N5*1.03 -> 3.708 | P5: =N5/1.13 -> 3.1858407 | Q5: =P5-J5 -> -0.36995598 | R5: =O5 -> 3.708 | V5: =G5*I5 -> 367.52 | W5: =R5*F5*I5/1.13 -> 131.25664 | X5: ='25年版cogs'!F6 -> 0.26981474 | Y5: ='25年版cogs'!G6 -> 0.025386209 | Z5: =W5-V5*(X5+Y5) -> 22.764386 | AA5: =Z5/W5 -> 0.17343417 | AC5: =P5*F5*I5 -> 127.43363 | AD5: =AC5-V5*(X5+Y5) -> 18.941377 | AE5: =AD5/AC5 -> 0.1486372 | AF5: 0.14847537 | AG5: 0.17 | AK5: 8.141 | AL5: =AK5*G5 -> 2991.9803
